Workbook

Sheet APRIL
A1: BRANDS | C1: VASU PHARMA DRUGS PVT LTD | E1: PRAKASH PHARMA DISTRIBUTORS | G1: Divya Pharma | I1: KEIMED PRIVATE LIMITED | K1: SAI SRIDHAR PHARMA PVT LTD | M1: SRI VENKATARAGHAVA AGENCIES | O1: SHREEJI DIST PVT LTD | Q1: SVS PHARMA | S1: PHARMA DISTRIBUTORS | U1: SAI PHARMA DISTRIBUTERS PVT LTD | W1: ALANKRITA AGENCIES | Y1: JAYA SURG & PHARMA PVT LTD | AA1: MANASA MEDICAL AGENCIES | AC1: KARTHICK AGENCIES | AE1: NIRMALA AGENCIES | AG1: HIMALAYA MEDICAL AGENCIES | AI1: Maruthi | AK1: LAXMI SAI MEDICAL AGENCIES | AM1: Patwari Pharma | AO1: Vishnu & Co | AQ1: SUMAN AGENCIES HYD PVT LTD | AS1: Sri Nirmala | AU1: SHREE SHARADA PHARMA | AW1: ALLIED PHARMA | AY1: GOEL DISTRIBUTER | BA1: KAMALESH PHARMA | BC1: ARVIND PHARMA DISTRIBUTER | BE1: GOEL PHARMA | BG1: KRISHNA PHARMACEUTICALS | BI1: AP DRUGS | BK1: MAWA PHARMACEUTICALS | BM1: TIRUMALA AGENCIES | BO1: SREE HARI MEDICALS | BQ1: SREE VENKATESHWARA MEDISOLUTIONS | BS1: SRI BALAJI DRUGS | BU1: VISHNU MEDICAL HALL | BW1: HYDERABAD SPECIALITY DRUGS | BY1: LORVEN PHARMA & SURGICALS (CORP) | CA1: AK PHARMA | CC1: OPTIVAL HEALTHSOLUTIONS | CE1: BALAJI MEDICAL AGENCIES | CG1: S42 | CI1: S43 | CK1: S44 | CM1: S45 | CO1: S46 | CQ1: S47 | CS1: S48 | CU1: S49 | CW1: S50 | CY1: BE TOTAL
B2: PTS | C2: Sale (Units) | D2: Closing Stock (Units) | E2: Sale (Units) | F2: Closing Stock (Units) | G2: Sale (Units) | H2: Closing Stock (Units) | I2: Sale (Units) | J2: Closing Stock (Units) | K2: Sale (Units) | L2: Closing Stock (Units) | M2: Sale (Units) | N2: Closing Stock (Units) | O2: Sale (Units) | P2: Closing Stock (Units) | Q2: Sale (Units) | R2: Closing Stock (Units) | S2: Sale (Units) | T2: Closing Stock (Units) | U2: Sale (Units) | V2: Closing Stock (Units) | W2: Sale (Units) | X2: Closing Stock (Units) | Y2: Sale (Units) | Z2: Closing Stock (Units) | AA2: Sale (Units) | AB2: Closing Stock (Units) | AC2: Sale (Units) | AD2: Closing Stock (Units) | AE2: Sale (Units) | AF2: Closing Stock (Units) | AG2: Sale (Units) | AH2: Closing Stock (Units) | AI2: Sale (Units) | AJ2: Closing Stock (Units) | AK2: Sale (Units) | AL2: Closing Stock (Units) | AM2: Sale (Units) | AN2: Closing Stock (Units) | AO2: Sale (Units) | AP2: Closing Stock (Units) | AQ2: Sale (Units) | AR2: Closing Stock (Units) | AS2: Sale (Units) | AT2: Closing Stock (Units) | AU2: Sale (Units) | AV2: Closing Stock (Units) | AW2: Sale (Units) | AX2: Closing Stock (Units) | AY2: Sale (Units) | AZ2: Closing Stock (Units) | BA2: Sale (Units) | BB2: Closing Stock (Units) | BC2: Sale (Units) | BD2: Closing Stock (Units) | BE2: Sale (Units) | BF2: Closing Stock (Units) | BG2: Sale (Units) | BH2: Closing Stock (Units) | BI2: Sale (Units) | BJ2: Closing Stock (Units) | BK2: Sale (Units) | BL2: Closing Stock (Units) | BM2: Sale (Units) | BN2: Closing Stock (Units) | BO2: Sale (Units) | BP2: Closing Stock (Units) | BQ2: Sale (Units) | BR2: Closing Stock (Units) | BS2: Sale (Units) | BT2: Closing Stock (Units) | BU2: Sale (Units) | BV2: Closing Stock (Units) | BW2: Sale (Units) | BX2: Closing Stock (Units) | BY2: Sale (Units) | BZ2: Closing Stock (Units) | CA2: Sale (Units) | CB2: Closing Stock (Units) | CC2: Sale (Units) | CD2: Closing Stock (Units) | CE2: Sale (Units) | CF2: Closing Stock (Units) | CG2: Sale (Units) | CH2: Closing Stock (Units) | CI2: Sale (Units) | CJ2: Closing Stock (Units) | CK2: Sale (Units) | CL2: Closing Stock (Units) | CM2: Sale (Units) | CN2: Closing Stock (Units) | CO2: Sale (Units) | CP2: Closing Stock (Units) | CQ2: Sale (Units) | CR2: Closing Stock (Units) | CS2: Sale (Units) | CT2: Closing Stock (Units) | CU2: Sale (Units) | CV2: Closing Stock (Units) | CW2: Sale (Units) | CX2: Closing Stock (Units) | CY2: Sale (Units) | CZ2: Closing Stock (Units)
A3: ALZIL - SR 23 10 TAB | B3: =IFERROR(VLOOKUP(A3,PRICELIST!$A$3:$D$138,4,0),"-") -> 167.79 | CY3: =C3+E3+G3+I3+K3+M3+O3+Q3+S3+U3+W3+Y3+AA3+AC3+AE3+AG3+AI3+AK3+AM3+AO3+AQ3+AS3+AU3+AW3+AY3+BA3+BC3+BE3+BG3+BI3+BK3+BM3+BO3+BQ3+BS3+BU3+BW3+BY3+CA3+CC3+CE3+CG3+CI3+CK3+CM3+CO3+CQ3+CS3+CU3+CW3 -> 0 | CZ3: =D3+F3+H3+J3+L3+N3+P3+R3+T3+V3+X3+Z3+AB3+AD3+AF3+AH3+AJ3+AL3+AN3+AP3+AR3+AT3+AV3+AX3+AZ3+BB3+BD3+BF3+BH3+BJ3+BL3+BN3+BP3+BR3+BT3+BV3+BX3+BZ3+CB3+CD3+CF3+CH3+CJ3+CL3+CN3+CP3+CR3+CT3+CV3+CX3 -> 0
A4: ALZIL- SR 11.5 10 TAB | B4: =IFERROR(VLOOKUP(A4,PRICELIST!$A$3:$D$138,4,0),"-") -> 112.5 | CY4: =C4+E4+G4+I4+K4+M4+O4+Q4+S4+U4+W4+Y4+AA4+AC4+AE4+AG4+AI4+AK4+AM4+AO4+AQ4+AS4+AU4+AW4+AY4+BA4+BC4+BE4+BG4+BI4+BK4+BM4+BO4+BQ4+BS4+BU4+BW4+BY4+CA4+CC4+CE4+CG4+CI4+CK4+CM4+CO4+CQ4+CS4+CU4+CW4 -> 0 | CZ4: =D4+F4+H4+J4+L4+N4+P4+R4+T4+V4+X4+Z4+AB4+AD4+AF4+AH4+AJ4+AL4+AN4+AP4+AR4+AT4+AV4+AX4+AZ4+BB4+BD4+BF4+BH4+BJ4+BL4+BN4+BP4+BR4+BT4+BV4+BX4+BZ4+CB4+CD4+CF4+CH4+CJ4+CL4+CN4+CP4+CR4+CT4+CV4+CX4 -> 0
A5: ALZIL-10 10 TAB | B5: =IFERROR(VLOOKUP(A5,PRICELIST!$A$3:$D$138,4,0),"-") -> 127.87 | C5: 10 | D5: 488 | G5: 13 | H5: 10 | I5: 2 | J5: 5 | P5: 10 | AB5: 30 | AJ5: 10 | AM5: 12 | AN5: 8 | AS5: 0 | AT5: 6 | AU5: 0 | AV5: 15 | BC5: 3 | BD5: 17 | CC5: 130 | CY5: =C5+E5+G5+I5+K5+M5+O5+Q5+S5+U5+W5+Y5+AA5+AC5+AE5+AG5+AI5+AK5+AM5+AO5+AQ5+AS5+AU5+AW5+AY5+BA5+BC5+BE5+BG5+BI5+BK5+BM5+BO5+BQ5+BS5+BU5+BW5+BY5+CA5+CC5+CE5+CG5+CI5+CK5+CM5+CO5+CQ5+CS5+CU5+CW5 -> 170 | CZ5: =D5+F5+H5+J5+L5+N5+P5+R5+T5+V5+X5+Z5+AB5+AD5+AF5+AH5+AJ5+AL5+AN5+AP5+AR5+AT5+AV5+AX5+AZ5+BB5+BD5+BF5+BH5+BJ5+BL5+BN5+BP5+BR5+BT5+BV5+BX5+BZ5+CB5+CD5+CF5+CH5+CJ5+CL5+CN5+CP5+CR5+CT5+CV5+CX5 -> 599
A6: ALZIL-5 10 TAB | B6: =IFERROR(VLOOKUP(A6,PRICELIST!$A$3:$D$138,4,0),"-") -> 88.7 | C6: 50 | D6: 256 | G6: 30 | H6: 25 | I6: 30 | J6: 15 | O6: 5 | P6: 3 | U6: 40 | V6: 24 | AA6: 18 | AB6: 24 | AI6: 11 | AJ6: 10 | AM6: 69 | AN6: 31 | AQ6: 0 | AR6: 30 | AS6: 18 | AT6: 7 | AU6: 6 | AV6: 12 | BE6: 7 | BF6: 3 | BU6: 6 | BV6: 14 | CC6: 120 | CY6: =C6+E6+G6+I6+K6+M6+O6+Q6+S6+U6+W6+Y6+AA6+AC6+AE6+AG6+AI6+AK6+AM6+AO6+AQ6+AS6+AU6+AW6+AY6+BA6+BC6+BE6+BG6+BI6+BK6+BM6+BO6+BQ6+BS6+BU6+BW6+BY6+CA6+CC6+CE6+CG6+CI6+CK6+CM6+CO6+CQ6+CS6+CU6+CW6 -> 410 | CZ6: =D6+F6+H6+J6+L6+N6+P6+R6+T6+V6+X6+Z6+AB6+AD6+AF6+AH6+AJ6+AL6+AN6+AP6+AR6+AT6+AV6+AX6+AZ6+BB6+BD6+BF6+BH6+BJ6+BL6+BN6+BP6+BR6+BT6+BV6+BX6+BZ6+CB6+CD6+CF6+CH6+CJ6+CL6+CN6+CP6+CR6+CT6+CV6+CX6 -> 454
A7: ALZIL M FORTE 10 TAB | B7: =IFERROR(VLOOKUP(A7,PRICELIST!$A$3:$D$138,4,0),"-") -> 171.64 | C7: 73 | D7: 246 | G7: 6 | H7: 14 | I7: 3 | J7: 6 | U7: 8 | V7: 8 | AI7: 1 | AJ7: 9 | AM7: 25 | AN7: 26 | AU7: 8 | AV7: 20 | CC7: 20 | CY7: =C7+E7+G7+I7+K7+M7+O7+Q7+S7+U7+W7+Y7+AA7+AC7+AE7+AG7+AI7+AK7+AM7+AO7+AQ7+AS7+AU7+AW7+AY7+BA7+BC7+BE7+BG7+BI7+BK7+BM7+BO7+BQ7+BS7+BU7+BW7+BY7+CA7+CC7+CE7+CG7+CI7+CK7+CM7+CO7+CQ7+CS7+CU7+CW7 -> 144 | CZ7: =D7+F7+H7+J7+L7+N7+P7+R7+T7+V7+X7+Z7+AB7+AD7+AF7+AH7+AJ7+AL7+AN7+AP7+AR7+AT7+AV7+AX7+AZ7+BB7+BD7+BF7+BH7+BJ7+BL7+BN7+BP7+BR7+BT7+BV7+BX7+BZ7+CB7+CD7+CF7+CH7+CJ7+CL7+CN7+CP7+CR7+CT7+CV7+CX7 -> 329
A8: ALZIL-M 10 10 TAB | B8: =IFERROR(VLOOKUP(A8,PRICELIST!$A$3:$D$138,4,0),"-") -> 216 | C8: 249 | D8: 807 | E8: 119 | F8: 32 | G8: 50 | H8: 30 | O8: 3 | P8: 10 | Q8: 20 | R8: 7 | S8: 0 | T8: 4 | U8: 41 | V8: 34 | W8: 1 | X8: 1 | AB8: 20 | AE8: 24 | AF8: 1 | AI8: 16 | AJ8: 41 | AM8: 78 | AN8: 22 | AQ8: 20 | AR8: 100 | AS8: 25 | AT8: 10 | AU8: 14 | AV8: 2 | AW8: 5 | AX8: 5 | BE8: 40 | BF8: 10 | CC8: 280 | CY8: =C8+E8+G8+I8+K8+M8+O8+Q8+S8+U8+W8+Y8+AA8+AC8+AE8+AG8+AI8+AK8+AM8+AO8+AQ8+AS8+AU8+AW8+AY8+BA8+BC8+BE8+BG8+BI8+BK8+BM8+BO8+BQ8+BS8+BU8+BW8+BY8+CA8+CC8+CE8+CG8+CI8+CK8+CM8+CO8+CQ8+CS8+CU8+CW8 -> 985 | CZ8: =D8+F8+H8+J8+L8+N8+P8+R8+T8+V8+X8+Z8+AB8+AD8+AF8+AH8+AJ8+AL8+AN8+AP8+AR8+AT8+AV8+AX8+AZ8+BB8+BD8+BF8+BH8+BJ8+BL8+BN8+BP8+BR8+BT8+BV8+BX8+BZ8+CB8+CD8+CF8+CH8+CJ8+CL8+CN8+CP8+CR8+CT8+CV8+CX8 -> 1136
A9: ALZIL-M 5 10 TAB | B9: =IFERROR(VLOOKUP(A9,PRICELIST!$A$3:$D$138,4,0),"-") -> 163.93 | C9: 186 | D9: 777 | E9: 81 | F9: 48 | Q9: 50 | R9: 5 | S9: 0 | T9: 2 | U9: 16 | V9: 12 | W9: 1 | X9: 6 | AB9: 40 | AE9: 28 | AF9: 0 | AI9: 15 | AJ9: 66 | AM9: 146 | AN9: 19 | AQ9: 7 | AR9: 73 | AS9: 25 | AT9: 0 | AU9: 13 | AV9: 0 | AW9: 6 | AX9: 4 | BE9: 6 | BF9: 4 | BQ9: 15 | BR9: 5 | CC9: 440 | CY9: =C9+E9+G9+I9+K9+M9+O9+Q9+S9+U9+W9+Y9+AA9+AC9+AE9+AG9+AI9+AK9+AM9+AO9+AQ9+AS9+AU9+AW9+AY9+BA9+BC9+BE9+BG9+BI9+BK9+BM9+BO9+BQ9+BS9+BU9+BW9+BY9+CA9+CC9+CE9+CG9+CI9+CK9+CM9+CO9+CQ9+CS9+CU9+CW9 -> 1035 | CZ9: =D9+F9+H9+J9+L9+N9+P9+R9+T9+V9+X9+Z9+AB9+AD9+AF9+AH9+AJ9+AL9+AN9+AP9+AR9+AT9+AV9+AX9+AZ9+BB9+BD9+BF9+BH9+BJ9+BL9+BN9+BP9+BR9+BT9+BV9+BX9+BZ9+CB9+CD9+CF9+CH9+CJ9+CL9+CN9+CP9+CR9+CT9+CV9+CX9 -> 1061
A10: ALZIL GROUP | C10: =SUMPRODUCT($B3:$B9,C3:C9) -> 102518.4 | D10: =SUMPRODUCT($B3:$B9,D3:D9) -> 429016.81 | E10: =SUMPRODUCT($B3:$B9,E3:E9) -> 38982.33 | F10: =SUMPRODUCT($B3:$B9,F3:F9) -> 14780.64 | G10: =SUMPRODUCT($B3:$B9,G3:G9) -> 16153.15 | H10: =SUMPRODUCT($B3:$B9,H3:H9) -> 12379.16 | I10: =SUMPRODUCT($B3:$B9,I3:I9) -> 3431.66 | J10: =SUMPRODUCT($B3:$B9,J3:J9) -> 2999.69 | ... CZ10: =SUMPRODUCT($B3:$B9,CZ3:CZ9) -> 592639.22
A11: BRIVAZEN 100 (15T) | B11: =IFERROR(VLOOKUP(A11,PRICELIST!$A$3:$D$138,4,0),"-") -> 432.21 | C11: 194 | D11: 660 | E11: 24 | F11: 2 | G11: 28 | H11: 24 | I11: 48 | J11: 28 | M11: 20 | N11: 42 | S11: 10 | U11: 28 | V11: 2 | W11: 49 | X11: 7 | AA11: 14 | AB11: 20 | AE11: 200 | AF11: 0 | AG11: 15 | AH11: 5 | AI11: 27 | AJ11: 20 | AK11: 0 | AL11: 30 | AM11: 29 | AN11: 8 | AO11: 0 | AP11: 1 | AQ11: 15 | AR11: 0 | AS11: 13 | AT11: 17 | AU11: 17 | AV11: 23 | BC11: 22 | BD11: 18 | BQ11: 6 | BR11: 4 | BS11: 7 | BT11: 3 | BV11: 18 | CA11: 7 | CB11: 3 | CC11: 160 | CY11: =C11+E11+G11+I11+K11+M11+O11+Q11+S11+U11+W11+Y11+AA11+AC11+AE11+AG11+AI11+AK11+AM11+AO11+AQ11+AS11+AU11+AW11+AY11+BA11+BC11+BE11+BG11+BI11+BK11+BM11+BO11+BQ11+BS11+BU11+BW11+BY11+CA11+CC11+CE11+CG11+CI11+CK11+CM11+CO11+CQ11+CS11+CU11+CW11 -> 933 | CZ11: =D11+F11+H11+J11+L11+N11+P11+R11+T11+V11+X11+Z11+AB11+AD11+AF11+AH11+AJ11+AL11+AN11+AP11+AR11+AT11+AV11+AX11+AZ11+BB11+BD11+BF11+BH11+BJ11+BL11+BN11+BP11+BR11+BT11+BV11+BX11+BZ11+CB11+CD11+CF11+CH11+CJ11+CL11+CN11+CP11+CR11+CT11+CV11+CX11 -> 935
A12: BRIVAZEN 25 (15T) | B12: =IFERROR(VLOOKUP(A12,PRICELIST!$A$3:$D$138,4,0),"-") -> 107.11 | C12: 102 | D12: 296 | F12: 16 | G12: 18 | H12: 20 | I12: 35 | J12: 25 | N12: 60 | P12: 24 | T12: 10 | U12: 17 | V12: 16 | W12: 29 | X12: 33 | AA12: 4 | AE12: 3 | AF12: 16 | AI12: 16 | AJ12: 32 | AK12: 5 | AL12: 6 | AM12: 15 | AN12: 24 | AS12: 10 | AT12: 9 | AU12: 14 | AV12: 18 | BC12: 20 | BD12: 20 | BK12: 5 | BL12: 6 | BV12: 27 | CC12: 60 | CY12: =C12+E12+G12+I12+K12+M12+O12+Q12+S12+U12+W12+Y12+AA12+AC12+AE12+AG12+AI12+AK12+AM12+AO12+AQ12+AS12+AU12+AW12+AY12+BA12+BC12+BE12+BG12+BI12+BK12+BM12+BO12+BQ12+BS12+BU12+BW12+BY12+CA12+CC12+CE12+CG12+CI12+CK12+CM12+CO12+CQ12+CS12+CU12+CW12 -> 353 | CZ12: =D12+F12+H12+J12+L12+N12+P12+R12+T12+V12+X12+Z12+AB12+AD12+AF12+AH12+AJ12+AL12+AN12+AP12+AR12+AT12+AV12+AX12+AZ12+BB12+BD12+BF12+BH12+BJ12+BL12+BN12+BP12+BR12+BT12+BV12+BX12+BZ12+CB12+CD12+CF12+CH12+CJ12+CL12+CN12+CP12+CR12+CT12+CV12+CX12 -> 658
A13: BRIVAZEN 50 (15T) | B13: =IFERROR(VLOOKUP(A13,PRICELIST!$A$3:$D$138,4,0),"-") -> 205.07 | C13: 1785 | D13: 5239 | E13: 132 | F13: 33 | G13: 75 | H13: 25 | I13: 471 | J13: 291 | M13: 183 | N13: 337 | O13: 7 | P13: 42 | Q13: 100 | R13: 20 | S13: 11 | T13: 5 | U13: 68 | V13: 42 | W13: 4 | X13: 14 | Y13: 40 | Z13: 70 | AA13: 75 | AB13: 69 | AC13: 30 | AD13: 34 | AE13: 217 | AF13: 61 | AG13: 14 | AH13: 6 | AI13: 103 | AJ13: 125 | AK13: 81 | AL13: 26 | AM13: 206 | AN13: 32 | AO13: 9 | AP13: 1 | AQ13: 60 | AR13: 100 | AS13: 18 | AT13: 22 | AU13: 57 | AV13: 21 | AW13: 7 | AX13: 3 | BD13: 20 | BG13: 21 | BH13: 22 | BK13: 10 | BL13: 5 | BQ13: 13 | BR13: 7 | BS13: 6 | BT13: 4 | BW13: 24 | CA13: 6 | CB13: 4 | CC13: 680 | CY13: =C13+E13+G13+I13+K13+M13+O13+Q13+S13+U13+W13+Y13+AA13+AC13+AE13+AG13+AI13+AK13+AM13+AO13+AQ13+AS13+AU13+AW13+AY13+BA13+BC13+BE13+BG13+BI13+BK13+BM13+BO13+BQ13+BS13+BU13+BW13+BY13+CA13+CC13+CE13+CG13+CI13+CK13+CM13+CO13+CQ13+CS13+CU13+CW13 -> 4513 | CZ13: =D13+F13+H13+J13+L13+N13+P13+R13+T13+V13+X13+Z13+AB13+AD13+AF13+AH13+AJ13+AL13+AN13+AP13+AR13+AT13+AV13+AX13+AZ13+BB13+BD13+BF13+BH13+BJ13+BL13+BN13+BP13+BR13+BT13+BV13+BX13+BZ13+CB13+CD13+CF13+CH13+CJ13+CL13+CN13+CP13+CR13+CT13+CV13+CX13 -> 6680
A14: BRIVAZEN 75 (15T) | B14: =IFERROR(VLOOKUP(A14,PRICELIST!$A$3:$D$138,4,0),"-") -> 322.71 | C14: 120 | D14: 270 | E14: 5 | F14: 15 | H14: 20 | I14: 36 | J14: 36 | O14: 7 | P14: 3 | S14: 20 | T14: 0 | U14: 9 | V14: 3 | X14: 14 | AA14: 76 | AB14: 34 | AE14: 64 | AF14: 6 | AI14: 11 | AJ14: 16 | AK14: 18 | AL14: 4 | AM14: 65 | AN14: 20 | AQ14: 2 | AR14: 30 | AU14: 19 | AV14: 13 | BG14: 6 | BH14: 24 | BQ14: 12 | BR14: 8 | BY14: 20 | CA14: 7 | CB14: 3 | CC14: 40 | CY14: =C14+E14+G14+I14+K14+M14+O14+Q14+S14+U14+W14+Y14+AA14+AC14+AE14+AG14+AI14+AK14+AM14+AO14+AQ14+AS14+AU14+AW14+AY14+BA14+BC14+BE14+BG14+BI14+BK14+BM14+BO14+BQ14+BS14+BU14+BW14+BY14+CA14+CC14+CE14+CG14+CI14+CK14+CM14+CO14+CQ14+CS14+CU14+CW14 -> 537 | CZ14: =D14+F14+H14+J14+L14+N14+P14+R14+T14+V14+X14+Z14+AB14+AD14+AF14+AH14+AJ14+AL14+AN14+AP14+AR14+AT14+AV14+AX14+AZ14+BB14+BD14+BF14+BH14+BJ14+BL14+BN14+BP14+BR14+BT14+BV14+BX14+BZ14+CB14+CD14+CF14+CH14+CJ14+CL14+CN14+CP14+CR14+CT14+CV14+CX14 -> 519
A15: BRIVAZEN SR 100 (SALE) (10T) | B15: =IFERROR(VLOOKUP(A15,PRICELIST!$A$3:$D$138,4,0),"-") -> 272.23 | C15: 65 | D15: 209 | E15: 6 | F15: 4 | G15: 18 | H15: 16 | I15: 3 | J15: 7 | M15: 54 | N15: 56 | Q15: 10 | S15: 5 | T15: 2 | U15: 30 | V15: 16 | AA15: 49 | AB15: 51 | AE15: 54 | AF15: 10 | AM15: 10 | AN15: 0 | AQ15: 19 | AR15: 31 | AS15: 11 | AT15: 9 | CC15: 30 | CY15: =C15+E15+G15+I15+K15+M15+O15+Q15+S15+U15+W15+Y15+AA15+AC15+AE15+AG15+AI15+AK15+AM15+AO15+AQ15+AS15+AU15+AW15+AY15+BA15+BC15+BE15+BG15+BI15+BK15+BM15+BO15+BQ15+BS15+BU15+BW15+BY15+CA15+CC15+CE15+CG15+CI15+CK15+CM15+CO15+CQ15+CS15+CU15+CW15 -> 364 | CZ15: =D15+F15+H15+J15+L15+N15+P15+R15+T15+V15+X15+Z15+AB15+AD15+AF15+AH15+AJ15+AL15+AN15+AP15+AR15+AT15+AV15+AX15+AZ15+BB15+BD15+BF15+BH15+BJ15+BL15+BN15+BP15+BR15+BT15+BV15+BX15+BZ15+CB15+CD15+CF15+CH15+CJ15+CL15+CN15+CP15+CR15+CT15+CV15+CX15 -> 411
A16: BRIVAZEN SR 200 (SALE) (10T) | B16: =IFERROR(VLOOKUP(A16,PRICELIST!$A$3:$D$138,4,0),"-") -> 352.76 | C16: 5 | D16: 54 | E16: -10 | F16: 20 | U16: 13 | V16: 12 | AM16: 0 | AN16: 10 | AU16: 3 | AV16: 7 | CY16: =C16+E16+G16+I16+K16+M16+O16+Q16+S16+U16+W16+Y16+AA16+AC16+AE16+AG16+AI16+AK16+AM16+AO16+AQ16+AS16+AU16+AW16+AY16+BA16+BC16+BE16+BG16+BI16+BK16+BM16+BO16+BQ16+BS16+BU16+BW16+BY16+CA16+CC16+CE16+CG16+CI16+CK16+CM16+CO16+CQ16+CS16+CU16+CW16 -> 11 | CZ16: =D16+F16+H16+J16+L16+N16+P16+R16+T16+V16+X16+Z16+AB16+AD16+AF16+AH16+AJ16+AL16+AN16+AP16+AR16+AT16+AV16+AX16+AZ16+BB16+BD16+BF16+BH16+BJ16+BL16+BN16+BP16+BR16+BT16+BV16+BX16+BZ16+CB16+CD16+CF16+CH16+CJ16+CL16+CN16+CP16+CR16+CT16+CV16+CX16 -> 103
A17: BRIVAZEN SR 50 (SALE) (10T) | B17: =IFERROR(VLOOKUP(A17,PRICELIST!$A$3:$D$138,4,0),"-") -> 137.57 | C17: 117 | D17: 265 | G17: 58 | H17: 27 | S17: 10 | T17: 0 | U17: 66 | V17: 24 | W17: 7 | X17: 18 | Y17: 30 | Z17: 30 | AA17: 6 | AB17: 1 | AE17: 39 | AF17: 11 | AI17: 24 | AJ17: 38 | AM17: 1 | AN17: 0 | AQ17: 10 | AR17: 50 | AU17: 0 | AV17: 7 | CC17: 30 | CY17: =C17+E17+G17+I17+K17+M17+O17+Q17+S17+U17+W17+Y17+AA17+AC17+AE17+AG17+AI17+AK17+AM17+AO17+AQ17+AS17+AU17+AW17+AY17+BA17+BC17+BE17+BG17+BI17+BK17+BM17+BO17+BQ17+BS17+BU17+BW17+BY17+CA17+CC17+CE17+CG17+CI17+CK17+CM17+CO17+CQ17+CS17+CU17+CW17 -> 398 | CZ17: =D17+F17+H17+J17+L17+N17+P17+R17+T17+V17+X17+Z17+AB17+AD17+AF17+AH17+AJ17+AL17+AN17+AP17+AR17+AT17+AV17+AX17+AZ17+BB17+BD17+BF17+BH17+BJ17+BL17+BN17+BP17+BR17+BT17+BV17+BX17+BZ17+CB17+CD17+CF17+CH17+CJ17+CL17+CN17+CP17+CR17+CT17+CV17+CX17 -> 471
A18: BRIVAZEN SOLUTION 200 ML | B18: =IFERROR(VLOOKUP(A18,PRICELIST!$A$3:$D$138,4,0),"-") -> 647.36 | C18: 20 | D18: 164 | U18: 3 | V18: 9 | AB18: 2 | AE18: 5 | AF18: 6 | CY18: =C18+E18+G18+I18+K18+M18+O18+Q18+S18+U18+W18+Y18+AA18+AC18+AE18+AG18+AI18+AK18+AM18+AO18+AQ18+AS18+AU18+AW18+AY18+BA18+BC18+BE18+BG18+BI18+BK18+BM18+BO18+BQ18+BS18+BU18+BW18+BY18+CA18+CC18+CE18+CG18+CI18+CK18+CM18+CO18+CQ18+CS18+CU18+CW18 -> 28 | CZ18: =D18+F18+H18+J18+L18+N18+P18+R18+T18+V18+X18+Z18+AB18+AD18+AF18+AH18+AJ18+AL18+AN18+AP18+AR18+AT18+AV18+AX18+AZ18+BB18+BD18+BF18+BH18+BJ18+BL18+BN18+BP18+BR18+BT18+BV18+BX18+BZ18+CB18+CD18+CF18+CH18+CJ18+CL18+CN18+CP18+CR18+CT18+CV18+CX18 -> 181
A19: BRIVAZEN INJECTION (5 ML) | B19: =IFERROR(VLOOKUP(A19,PRICELIST!$A$3:$D$138,4,0),"-") -> 110.25 | C19: 100 | D19: 40 | E19: 6 | F19: 25 | N19: 50 | R19: 50 | S19: 40 | T19: 2 | U19: 125 | V19: 112 | AA19: 168 | AB19: 44 | AC19: 72 | AD19: 50 | AF19: 70 | AI19: 175 | AJ19: 63 | AM19: 0 | AN19: 10 | BS19: 5 | BT19: 5 | CY19: =C19+E19+G19+I19+K19+M19+O19+Q19+S19+U19+W19+Y19+AA19+AC19+AE19+AG19+AI19+AK19+AM19+AO19+AQ19+AS19+AU19+AW19+AY19+BA19+BC19+BE19+BG19+BI19+BK19+BM19+BO19+BQ19+BS19+BU19+BW19+BY19+CA19+CC19+CE19+CG19+CI19+CK19+CM19+CO19+CQ19+CS19+CU19+CW19 -> 691 | CZ19: =D19+F19+H19+J19+L19+N19+P19+R19+T19+V19+X19+Z19+AB19+AD19+AF19+AH19+AJ19+AL19+AN19+AP19+AR19+AT19+AV19+AX19+AZ19+BB19+BD19+BF19+BH19+BJ19+BL19+BN19+BP19+BR19+BT19+BV19+BX19+BZ19+CB19+CD19+CF19+CH19+CJ19+CL19+CN19+CP19+CR19+CT19+CV19+CX19 -> 521
A20: BRIVAZEN GROUP | C20: =SUMPRODUCT($B11:$B19,C11:C19) -> 559075.75 | D20: =SUMPRODUCT($B11:$B19,D11:D19) -> 1701434.8 | E20: =SUMPRODUCT($B11:$B19,E11:E19) -> 37823.11 | F20: =SUMPRODUCT($B11:$B19,F11:F19) -> 25086.51 | G20: =SUMPRODUCT($B11:$B19,G11:G19) -> 42289.31 | H20: =SUMPRODUCT($B11:$B19,H11:H19) -> 32166.26 | I20: =SUMPRODUCT($B11:$B19,I11:I19) -> 133517.15 | J20: =SUMPRODUCT($B11:$B19,J11:J19) -> 87978.17 | ... CZ20: =SUMPRODUCT($B11:$B19,CZ11:CZ19) -> 2399577.5
A21: CELETOIN -100, 100 TABS (D) | B21: =IFERROR(VLOOKUP(A21,PRICELIST!$A$3:$D$138,4,0),"-") -> 128.88 | C21: 14 | D21: 96 | G21: 14 | H21: 13 | I21: 61 | J21: 52 | AI21: 3 | AJ21: 4 | AM21: 0 | AN21: 1 | AS21: 2 | AT21: 4 | BU21: 5 | BV21: 2 | CC21: 10 | CY21: =C21+E21+G21+I21+K21+M21+O21+Q21+S21+U21+W21+Y21+AA21+AC21+AE21+AG21+AI21+AK21+AM21+AO21+AQ21+AS21+AU21+AW21+AY21+BA21+BC21+BE21+BG21+BI21+BK21+BM21+BO21+BQ21+BS21+BU21+BW21+BY21+CA21+CC21+CE21+CG21+CI21+CK21+CM21+CO21+CQ21+CS21+CU21+CW21 -> 109 | CZ21: =D21+F21+H21+J21+L21+N21+P21+R21+T21+V21+X21+Z21+AB21+AD21+AF21+AH21+AJ21+AL21+AN21+AP21+AR21+AT21+AV21+AX21+AZ21+BB21+BD21+BF21+BH21+BJ21+BL21+BN21+BP21+BR21+BT21+BV21+BX21+BZ21+CB21+CD21+CF21+CH21+CJ21+CL21+CN21+CP21+CR21+CT21+CV21+CX21 -> 172
A22: CELETOIN 300 30 TAB | B22: =IFERROR(VLOOKUP(A22,PRICELIST!$A$3:$D$138,4,0),"-") -> 120.53 | D22: 10 | I22: 4 | J22: 13 | AM22: 0 | AN22: 10 | CY22: =C22+E22+G22+I22+K22+M22+O22+Q22+S22+U22+W22+Y22+AA22+AC22+AE22+AG22+AI22+AK22+AM22+AO22+AQ22+AS22+AU22+AW22+AY22+BA22+BC22+BE22+BG22+BI22+BK22+BM22+BO22+BQ22+BS22+BU22+BW22+BY22+CA22+CC22+CE22+CG22+CI22+CK22+CM22+CO22+CQ22+CS22+CU22+CW22 -> 4 | CZ22: =D22+F22+H22+J22+L22+N22+P22+R22+T22+V22+X22+Z22+AB22+AD22+AF22+AH22+AJ22+AL22+AN22+AP22+AR22+AT22+AV22+AX22+AZ22+BB22+BD22+BF22+BH22+BJ22+BL22+BN22+BP22+BR22+BT22+BV22+BX22+BZ22+CB22+CD22+CF22+CH22+CJ22+CL22+CN22+CP22+CR22+CT22+CV22+CX22 -> 33
A23: CELETOIN ER 300 30 TAB | B23: =IFERROR(VLOOKUP(A23,PRICELIST!$A$3:$D$138,4,0),"-") -> 144.29 | D23: 10 | AI23: 1 | AJ23: 8 | AM23: 1 | AN23: 13 | CY23: =C23+E23+G23+I23+K23+M23+O23+Q23+S23+U23+W23+Y23+AA23+AC23+AE23+AG23+AI23+AK23+AM23+AO23+AQ23+AS23+AU23+AW23+AY23+BA23+BC23+BE23+BG23+BI23+BK23+BM23+BO23+BQ23+BS23+BU23+BW23+BY23+CA23+CC23+CE23+CG23+CI23+CK23+CM23+CO23+CQ23+CS23+CU23+CW23 -> 2 | CZ23: =D23+F23+H23+J23+L23+N23+P23+R23+T23+V23+X23+Z23+AB23+AD23+AF23+AH23+AJ23+AL23+AN23+AP23+AR23+AT23+AV23+AX23+AZ23+BB23+BD23+BF23+BH23+BJ23+BL23+BN23+BP23+BR23+BT23+BV23+BX23+BZ23+CB23+CD23+CF23+CH23+CJ23+CL23+CN23+CP23+CR23+CT23+CV23+CX23 -> 31
A24: CELETOIN GROUP | C24: =SUMPRODUCT($B21:$B23,C21:C23) -> 1804.32 | D24: =SUMPRODUCT($B21:$B23,D21:D23) -> 15020.68 | E24: =SUMPRODUCT($B21:$B23,E21:E23) -> 0 | F24: =SUMPRODUCT($B21:$B23,F21:F23) -> 0 | G24: =SUMPRODUCT($B21:$B23,G21:G23) -> 1804.32 | H24: =SUMPRODUCT($B21:$B23,H21:H23) -> 1675.44 | I24: =SUMPRODUCT($B21:$B23,I21:I23) -> 8343.8 | J24: =SUMPRODUCT($B21:$B23,J21:J23) -> 8268.65 | ... CZ24: =SUMPRODUCT($B21:$B23,CZ21:CZ23) -> 30617.84
A25: LURASID 40 (10T) | B25: =IFERROR(VLOOKUP(A25,PRICELIST!$A$3:$D$138,4,0),"-") -> 110.57 | C25: 18 | D25: 124 | E25: 3 | F25: 28 | G25: 33 | H25: 20 | I25: 57 | J25: 40 | T25: 26 | X25: 10 | AI25: 6 | AJ25: 18 | AM25: 0 | AN25: 6 | AS25: 17 | AT25: 10 | AU25: 25 | AV25: 18 | BQ25: 4 | BR25: 6 | BU25: 47 | BV25: 32 | CC25: 140 | CY25: =C25+E25+G25+I25+K25+M25+O25+Q25+S25+U25+W25+Y25+AA25+AC25+AE25+AG25+AI25+AK25+AM25+AO25+AQ25+AS25+AU25+AW25+AY25+BA25+BC25+BE25+BG25+BI25+BK25+BM25+BO25+BQ25+BS25+BU25+BW25+BY25+CA25+CC25+CE25+CG25+CI25+CK25+CM25+CO25+CQ25+CS25+CU25+CW25 -> 350 | CZ25: =D25+F25+H25+J25+L25+N25+P25+R25+T25+V25+X25+Z25+AB25+AD25+AF25+AH25+AJ25+AL25+AN25+AP25+AR25+AT25+AV25+AX25+AZ25+BB25+BD25+BF25+BH25+BJ25+BL25+BN25+BP25+BR25+BT25+BV25+BX25+BZ25+CB25+CD25+CF25+CH25+CJ25+CL25+CN25+CP25+CR25+CT25+CV25+CX25 -> 338
A26: LURASID 80 (10T) | B26: =IFERROR(VLOOKUP(A26,PRICELIST!$A$3:$D$138,4,0),"-") -> 184.82 | C26: 10 | D26: 70 | H26: 13 | I26: 0 | J26: 21 | AI26: 9 | AJ26: 11 | AS26: 3 | AT26: 1 | AU26: 3 | AV26: 14 | CC26: 50 | CY26: =C26+E26+G26+I26+K26+M26+O26+Q26+S26+U26+W26+Y26+AA26+AC26+AE26+AG26+AI26+AK26+AM26+AO26+AQ26+AS26+AU26+AW26+AY26+BA26+BC26+BE26+BG26+BI26+BK26+BM26+BO26+BQ26+BS26+BU26+BW26+BY26+CA26+CC26+CE26+CG26+CI26+CK26+CM26+CO26+CQ26+CS26+CU26+CW26 -> 75 | CZ26: =D26+F26+H26+J26+L26+N26+P26+R26+T26+V26+X26+Z26+AB26+AD26+AF26+AH26+AJ26+AL26+AN26+AP26+AR26+AT26+AV26+AX26+AZ26+BB26+BD26+BF26+BH26+BJ26+BL26+BN26+BP26+BR26+BT26+BV26+BX26+BZ26+CB26+CD26+CF26+CH26+CJ26+CL26+CN26+CP26+CR26+CT26+CV26+CX26 -> 130
A27: LURASID GROUP | C27: =SUMPRODUCT($B25:$B26,C25:C26) -> 3838.46 | D27: =SUMPRODUCT($B25:$B26,D25:D26) -> 26648.08 | E27: =SUMPRODUCT($B25:$B26,E25:E26) -> 331.71 | F27: =SUMPRODUCT($B25:$B26,F25:F26) -> 3095.96 | G27: =SUMPRODUCT($B25:$B26,G25:G26) -> 3648.81 | H27: =SUMPRODUCT($B25:$B26,H25:H26) -> 4614.06 | I27: =SUMPRODUCT($B25:$B26,I25:I26) -> 6302.49 | J27: =SUMPRODUCT($B25:$B26,J25:J26) -> 8304.02 | ... CZ27: =SUMPRODUCT($B25:$B26,CZ25:CZ26) -> 61399.26
A28: MIRNITE MELTAB-15 10 TAB | B28: =IFERROR(VLOOKUP(A28,PRICELIST!$A$3:$D$138,4,0),"-") -> 113.79 | C28: 43 | D28: 29 | H28: 14 | I28: 7 | J28: 7 | N28: 108 | T28: 7 | AF28: 10 | AO28: 6 | AP28: 4 | AQ28: 0 | AR28: 2 | AS28: 0 | AT28: 7 | AU28: 5 | AV28: 22 | BQ28: 5 | BR28: 5 | BU28: 10 | BV28: 10 | CC28: 60 | CY28: =C28+E28+G28+I28+K28+M28+O28+Q28+S28+U28+W28+Y28+AA28+AC28+AE28+AG28+AI28+AK28+AM28+AO28+AQ28+AS28+AU28+AW28+AY28+BA28+BC28+BE28+BG28+BI28+BK28+BM28+BO28+BQ28+BS28+BU28+BW28+BY28+CA28+CC28+CE28+CG28+CI28+CK28+CM28+CO28+CQ28+CS28+CU28+CW28 -> 136 | CZ28: =D28+F28+H28+J28+L28+N28+P28+R28+T28+V28+X28+Z28+AB28+AD28+AF28+AH28+AJ28+AL28+AN28+AP28+AR28+AT28+AV28+AX28+AZ28+BB28+BD28+BF28+BH28+BJ28+BL28+BN28+BP28+BR28+BT28+BV28+BX28+BZ28+CB28+CD28+CF28+CH28+CJ28+CL28+CN28+CP28+CR28+CT28+CV28+CX28 -> 225
A29: MIRNITE MELTAB-30 10 TAB | B29: =IFERROR(VLOOKUP(A29,PRICELIST!$A$3:$D$138,4,0),"-") -> 188.04 | C29: 20 | D29: 84 | F29: 10 | G29: 3 | H29: 2 | N29: 74 | AM29: 4 | AN29: 2 | AO29: 0 | AP29: 10 | AU29: 0 | AV29: 11 | BU29: 10 | BV29: 10 | CY29: =C29+E29+G29+I29+K29+M29+O29+Q29+S29+U29+W29+Y29+AA29+AC29+AE29+AG29+AI29+AK29+AM29+AO29+AQ29+AS29+AU29+AW29+AY29+BA29+BC29+BE29+BG29+BI29+BK29+BM29+BO29+BQ29+BS29+BU29+BW29+BY29+CA29+CC29+CE29+CG29+CI29+CK29+CM29+CO29+CQ29+CS29+CU29+CW29 -> 37 | CZ29: =D29+F29+H29+J29+L29+N29+P29+R29+T29+V29+X29+Z29+AB29+AD29+AF29+AH29+AJ29+AL29+AN29+AP29+AR29+AT29+AV29+AX29+AZ29+BB29+BD29+BF29+BH29+BJ29+BL29+BN29+BP29+BR29+BT29+BV29+BX29+BZ29+CB29+CD29+CF29+CH29+CJ29+CL29+CN29+CP29+CR29+CT29+CV29+CX29 -> 203
A30: MIRNITE MELTAB-7.5 10 TAB | B30: =IFERROR(VLOOKUP(A30,PRICELIST!$A$3:$D$138,4,0),"-") -> 68.16 | C30: 43 | D30: 128 | G30: 19 | H30: 25 | I30: 4 | J30: 12 | S30: 27 | W30: 1 | Z30: 2 | AJ30: 32 | AM30: 9 | AN30: 1 | AO30: 0 | AP30: 4 | AQ30: 6 | AR30: 24 | AS30: 3 | AT30: 12 | AU30: 14 | AV30: 20 | AW30: 6 | AX30: 4 | BE30: 15 | BF30: 5 | BU30: 4 | BV30: 20 | CC30: 20 | CY30: =C30+E30+G30+I30+K30+M30+O30+Q30+S30+U30+W30+Y30+AA30+AC30+AE30+AG30+AI30+AK30+AM30+AO30+AQ30+AS30+AU30+AW30+AY30+BA30+BC30+BE30+BG30+BI30+BK30+BM30+BO30+BQ30+BS30+BU30+BW30+BY30+CA30+CC30+CE30+CG30+CI30+CK30+CM30+CO30+CQ30+CS30+CU30+CW30 -> 171 | CZ30: =D30+F30+H30+J30+L30+N30+P30+R30+T30+V30+X30+Z30+AB30+AD30+AF30+AH30+AJ30+AL30+AN30+AP30+AR30+AT30+AV30+AX30+AZ30+BB30+BD30+BF30+BH30+BJ30+BL30+BN30+BP30+BR30+BT30+BV30+BX30+BZ30+CB30+CD30+CF30+CH30+CJ30+CL30+CN30+CP30+CR30+CT30+CV30+CX30 -> 289
A31: MIRNITE-15 10 TAB | B31: =IFERROR(VLOOKUP(A31,PRICELIST!$A$3:$D$138,4,0),"-") -> 101.57 | C31: 93 | D31: 299 | E31: 9 | F31: 11 | I31: 5 | J31: 9 | O31: 2 | S31: 12 | T31: 9 | U31: 1 | V31: 10 | W31: 3 | X31: 3 | AC31: 5 | AD31: 6 | AF31: 10 | AI31: 3 | AJ31: 61 | AM31: 34 | AN31: 6 | AO31: 0 | AP31: 10 | AQ31: 8 | AR31: 0 | AS31: 0 | AT31: 10 | AU31: 7 | AV31: 7 | BE31: 6 | BF31: 4 | BU31: 9 | BV31: 9 | BY31: 740 | CC31: 70 | CY31: =C31+E31+G31+I31+K31+M31+O31+Q31+S31+U31+W31+Y31+AA31+AC31+AE31+AG31+AI31+AK31+AM31+AO31+AQ31+AS31+AU31+AW31+AY31+BA31+BC31+BE31+BG31+BI31+BK31+BM31+BO31+BQ31+BS31+BU31+BW31+BY31+CA31+CC31+CE31+CG31+CI31+CK31+CM31+CO31+CQ31+CS31+CU31+CW31 -> 1007 | CZ31: =D31+F31+H31+J31+L31+N31+P31+R31+T31+V31+X31+Z31+AB31+AD31+AF31+AH31+AJ31+AL31+AN31+AP31+AR31+AT31+AV31+AX31+AZ31+BB31+BD31+BF31+BH31+BJ31+BL31+BN31+BP31+BR31+BT31+BV31+BX31+BZ31+CB31+CD31+CF31+CH31+CJ31+CL31+CN31+CP31+CR31+CT31+CV31+CX31 -> 464
A32: MIRNITE-30 10 TAB | B32: =IFERROR(VLOOKUP(A32,PRICELIST!$A$3:$D$138,4,0),"-") -> 164.73 | C32: 43 | D32: 174 | E32: 5 | F32: 3 | G32: 9 | H32: 18 | I32: 0 | J32: 8 | O32: 1 | P32: 1 | S32: 0 | T32: 2 | U32: 2 | V32: 6 | AI32: 3 | AJ32: 2 | AM32: 28 | AN32: 16 | AO32: 3 | AP32: 7 | AQ32: 6 | AR32: 14 | AU32: 9 | AV32: 14 | BU32: 6 | BV32: 12 | CC32: 10 | CY32: =C32+E32+G32+I32+K32+M32+O32+Q32+S32+U32+W32+Y32+AA32+AC32+AE32+AG32+AI32+AK32+AM32+AO32+AQ32+AS32+AU32+AW32+AY32+BA32+BC32+BE32+BG32+BI32+BK32+BM32+BO32+BQ32+BS32+BU32+BW32+BY32+CA32+CC32+CE32+CG32+CI32+CK32+CM32+CO32+CQ32+CS32+CU32+CW32 -> 125 | CZ32: =D32+F32+H32+J32+L32+N32+P32+R32+T32+V32+X32+Z32+AB32+AD32+AF32+AH32+AJ32+AL32+AN32+AP32+AR32+AT32+AV32+AX32+AZ32+BB32+BD32+BF32+BH32+BJ32+BL32+BN32+BP32+BR32+BT32+BV32+BX32+BZ32+CB32+CD32+CF32+CH32+CJ32+CL32+CN32+CP32+CR32+CT32+CV32+CX32 -> 277
A33: MIRNITE-7.5 10 TAB | B33: =IFERROR(VLOOKUP(A33,PRICELIST!$A$3:$D$138,4,0),"-") -> 78.1 | C33: 138 | D33: 231 | E33: 5 | G33: 45 | H33: 26 | I33: 28 | J33: 28 | T33: 10 | U33: 18 | V33: 9 | X33: 12 | Y33: 54 | AM33: 128 | AN33: 34 | AO33: 0 | AP33: 0 | AQ33: 6 | AR33: 24 | AS33: 0 | AT33: 35 | AU33: 4 | AV33: 19 | BC33: 5 | BD33: 3 | BE33: 14 | BF33: 6 | BU33: 1 | BV33: 7 | BY33: 1000 | CA33: 7 | CB33: 3 | CC33: 150 | CY33: =C33+E33+G33+I33+K33+M33+O33+Q33+S33+U33+W33+Y33+AA33+AC33+AE33+AG33+AI33+AK33+AM33+AO33+AQ33+AS33+AU33+AW33+AY33+BA33+BC33+BE33+BG33+BI33+BK33+BM33+BO33+BQ33+BS33+BU33+BW33+BY33+CA33+CC33+CE33+CG33+CI33+CK33+CM33+CO33+CQ33+CS33+CU33+CW33 -> 1603 | CZ33: =D33+F33+H33+J33+L33+N33+P33+R33+T33+V33+X33+Z33+AB33+AD33+AF33+AH33+AJ33+AL33+AN33+AP33+AR33+AT33+AV33+AX33+AZ33+BB33+BD33+BF33+BH33+BJ33+BL33+BN33+BP33+BR33+BT33+BV33+BX33+BZ33+CB33+CD33+CF33+CH33+CJ33+CL33+CN33+CP33+CR33+CT33+CV33+CX33 -> 447
A34: MIRNITE GROUP | C34: =SUMPRODUCT($B28:$B33,C28:C33) -> 38891.85 | D34: =SUMPRODUCT($B28:$B33,D28:D33) -> 104893.3 | E34: =SUMPRODUCT($B28:$B33,E28:E33) -> 2128.28 | F34: =SUMPRODUCT($B28:$B33,F28:F33) -> 3491.86 | G34: =SUMPRODUCT($B28:$B33,G28:G33) -> 6856.23 | H34: =SUMPRODUCT($B28:$B33,H28:H33) -> 8668.88 | I34: =SUMPRODUCT($B28:$B33,I28:I33) -> 3763.82 | J34: =SUMPRODUCT($B28:$B33,J28:J33) -> 6033.22 | ... CZ34: =SUMPRODUCT($B28:$B33,CZ28:CZ33) -> 211142.5
A35: NAPRA-D 250 10 TAB | B35: =IFERROR(VLOOKUP(A35,PRICELIST!$A$3:$D$138,4,0),"-") -> 60.11 | C35: 368 | D35: 1402 | E35: 16 | F35: 24 | G35: 56 | H35: 38 | I35: 586 | J35: 470 | M35: 185 | N35: 200 | O35: 4 | P35: 164 | U35: 65 | V35: 27 | W35: 9 | X35: 21 | AA35: 31 | AB35: 39 | AC35: 20 | AD35: 33 | AE35: 312 | AF35: 13 | AG35: 14 | AH35: 6 | AI35: 34 | AJ35: 158 | AK35: 15 | AL35: 53 | AM35: 280 | AN35: 210 | AO35: 9 | AP35: 0 | AQ35: 96 | AR35: 104 | AS35: 28 | AT35: 23 | BD35: 10 | BE35: 50 | BF35: 20 | BG35: 5 | BI35: 12 | BJ35: 9 | BK35: 7 | BL35: 13 | BQ35: 12 | BR35: 8 | BS35: 6 | BT35: 4 | BU35: 9 | BV35: 40 | BW35: 70 | BY35: 299 | CC35: 380 | CY35: =C35+E35+G35+I35+K35+M35+O35+Q35+S35+U35+W35+Y35+AA35+AC35+AE35+AG35+AI35+AK35+AM35+AO35+AQ35+AS35+AU35+AW35+AY35+BA35+BC35+BE35+BG35+BI35+BK35+BM35+BO35+BQ35+BS35+BU35+BW35+BY35+CA35+CC35+CE35+CG35+CI35+CK35+CM35+CO35+CQ35+CS35+CU35+CW35 -> 2978 | CZ35: =D35+F35+H35+J35+L35+N35+P35+R35+T35+V35+X35+Z35+AB35+AD35+AF35+AH35+AJ35+AL35+AN35+AP35+AR35+AT35+AV35+AX35+AZ35+BB35+BD35+BF35+BH35+BJ35+BL35+BN35+BP35+BR35+BT35+BV35+BX35+BZ35+CB35+CD35+CF35+CH35+CJ35+CL35+CN35+CP35+CR35+CT35+CV35+CX35 -> 3089
A36: NAPRA-D 500 10 TAB | B36: =IFERROR(VLOOKUP(A36,PRICELIST!$A$3:$D$138,4,0),"-") -> 91.2 | C36: 418 | D36: 1331 | E36: 46 | F36: 20 | G36: 65 | H36: 47 | I36: 1212 | J36: 712 | M36: 209 | N36: 177 | O36: 30 | P36: 31 | Q36: 180 | R36: 2 | S36: 5 | T36: 5 | U36: 137 | V36: 6 | W36: 9 | X36: 21 | Y36: 1 | Z36: 10 | AA36: 44 | AB36: 25 | AC36: 15 | AD36: 15 | AE36: 304 | AF36: 27 | AG36: 20 | AH36: 10 | AI36: 53 | AJ36: 48 | AK36: 25 | AL36: 54 | AM36: 486 | AN36: 208 | AO36: 10 | AP36: 0 | AS36: 58 | AT36: 32 | AU36: 30 | AV36: 7 | AW36: 7 | AX36: 3 | BB36: 10 | BE36: 30 | BF36: 10 | BG36: 32 | BI36: 10 | BJ36: 5 | BK36: 10 | BQ36: 20 | BR36: 10 | BS36: 7 | BT36: 3 | BU36: 2 | BV36: 5 | BW36: 30 | BY36: 391 | CC36: 720 | CY36: =C36+E36+G36+I36+K36+M36+O36+Q36+S36+U36+W36+Y36+AA36+AC36+AE36+AG36+AI36+AK36+AM36+AO36+AQ36+AS36+AU36+AW36+AY36+BA36+BC36+BE36+BG36+BI36+BK36+BM36+BO36+BQ36+BS36+BU36+BW36+BY36+CA36+CC36+CE36+CG36+CI36+CK36+CM36+CO36+CQ36+CS36+CU36+CW36 -> 4616 | CZ36: =D36+F36+H36+J36+L36+N36+P36+R36+T36+V36+X36+Z36+AB36+AD36+AF36+AH36+AJ36+AL36+AN36+AP36+AR36+AT36+AV36+AX36+AZ36+BB36+BD36+BF36+BH36+BJ36+BL36+BN36+BP36+BR36+BT36+BV36+BX36+BZ36+CB36+CD36+CF36+CH36+CJ36+CL36+CN36+CP36+CR36+CT36+CV36+CX36 -> 2834
A37: NAPRA D GROUP | C37: =SUMPRODUCT($B35:$B36,C35:C36) -> 60242.08 | D37: =SUMPRODUCT($B35:$B36,D35:D36) -> 205661.42 | E37: =SUMPRODUCT($B35:$B36,E35:E36) -> 5156.96 | F37: =SUMPRODUCT($B35:$B36,F35:F36) -> 3266.64 | G37: =SUMPRODUCT($B35:$B36,G35:G36) -> 9294.16 | H37: =SUMPRODUCT($B35:$B36,H35:H36) -> 6570.58 | I37: =SUMPRODUCT($B35:$B36,I35:I36) -> 145758.86 | J37: =SUMPRODUCT($B35:$B36,J35:J36) -> 93186.1 | ... CZ37: =SUMPRODUCT($B35:$B36,CZ35:CZ36) -> 444140.59
A38: NEMDAA 10 10 TAB | B38: =IFERROR(VLOOKUP(A38,PRICELIST!$A$3:$D$138,4,0),"-") -> 159.75 | C38: 78 | D38: 180 | G38: 14 | H38: 27 | I38: 23 | J38: 23 | P38: 10 | S38: 12 | T38: 6 | AM38: 33 | AN38: 7 | AQ38: 6 | AR38: 0 | AS38: 6 | AT38: 10 | BQ38: 6 | BR38: 4 | CC38: 210 | CY38: =C38+E38+G38+I38+K38+M38+O38+Q38+S38+U38+W38+Y38+AA38+AC38+AE38+AG38+AI38+AK38+AM38+AO38+AQ38+AS38+AU38+AW38+AY38+BA38+BC38+BE38+BG38+BI38+BK38+BM38+BO38+BQ38+BS38+BU38+BW38+BY38+CA38+CC38+CE38+CG38+CI38+CK38+CM38+CO38+CQ38+CS38+CU38+CW38 -> 388 | CZ38: =D38+F38+H38+J38+L38+N38+P38+R38+T38+V38+X38+Z38+AB38+AD38+AF38+AH38+AJ38+AL38+AN38+AP38+AR38+AT38+AV38+AX38+AZ38+BB38+BD38+BF38+BH38+BJ38+BL38+BN38+BP38+BR38+BT38+BV38+BX38+BZ38+CB38+CD38+CF38+CH38+CJ38+CL38+CN38+CP38+CR38+CT38+CV38+CX38 -> 267
A39: NEMDAA 5 10 TAB | B39: =IFERROR(VLOOKUP(A39,PRICELIST!$A$3:$D$138,4,0),"-") -> 83.59 | C39: 43 | D39: 139 | I39: 7 | J39: 12 | AM39: 8 | AN39: 1 | AQ39: 0 | AR39: 30 | CC39: 80 | CY39: =C39+E39+G39+I39+K39+M39+O39+Q39+S39+U39+W39+Y39+AA39+AC39+AE39+AG39+AI39+AK39+AM39+AO39+AQ39+AS39+AU39+AW39+AY39+BA39+BC39+BE39+BG39+BI39+BK39+BM39+BO39+BQ39+BS39+BU39+BW39+BY39+CA39+CC39+CE39+CG39+CI39+CK39+CM39+CO39+CQ39+CS39+CU39+CW39 -> 138 | CZ39: =D39+F39+H39+J39+L39+N39+P39+R39+T39+V39+X39+Z39+AB39+AD39+AF39+AH39+AJ39+AL39+AN39+AP39+AR39+AT39+AV39+AX39+AZ39+BB39+BD39+BF39+BH39+BJ39+BL39+BN39+BP39+BR39+BT39+BV39+BX39+BZ39+CB39+CD39+CF39+CH39+CJ39+CL39+CN39+CP39+CR39+CT39+CV39+CX39 -> 182
A40: NEMDAA GROUP | C40: =SUMPRODUCT($B38:$B39,C38:C39) -> 16054.87 | D40: =SUMPRODUCT($B38:$B39,D38:D39) -> 40374.01 | E40: =SUMPRODUCT($B38:$B39,E38:E39) -> 0 | F40: =SUMPRODUCT($B38:$B39,F38:F39) -> 0 | G40: =SUMPRODUCT($B38:$B39,G38:G39) -> 2236.5 | H40: =SUMPRODUCT($B38:$B39,H38:H39) -> 4313.25 | I40: =SUMPRODUCT($B38:$B39,I38:I39) -> 4259.38 | J40: =SUMPRODUCT($B38:$B39,J38:J39) -> 4677.33 | ... CZ40: =SUMPRODUCT($B38:$B39,CZ38:CZ39) -> 57866.63
...

Sheet MAY
A1: BRANDS | C1: =APRIL!C1 -> VASU PHARMA DRUGS PVT LTD | E1: =APRIL!E1 -> PRAKASH PHARMA DISTRIBUTORS | G1: =APRIL!G1 -> Divya Pharma | I1: =APRIL!I1 -> KEIMED PRIVATE LIMITED | K1: =APRIL!K1 -> SAI SRIDHAR PHARMA PVT LTD | M1: =APRIL!M1 -> SRI VENKATARAGHAVA AGENCIES | O1: =APRIL!O1 -> SHREEJI DIST PVT LTD | Q1: =APRIL!Q1 -> SVS PHARMA | S1: =APRIL!S1 -> PHARMA DISTRIBUTORS | U1: =APRIL!U1 -> SAI PHARMA DISTRIBUTERS PVT LTD | W1: =APRIL!W1 -> ALANKRITA AGENCIES | Y1: =APRIL!Y1 -> JAYA SURG & PHARMA PVT LTD | AA1: =APRIL!AA1 -> MANASA MEDICAL AGENCIES | AC1: =APRIL!AC1 -> KARTHICK AGENCIES | AE1: =APRIL!AE1 -> NIRMALA AGENCIES | AG1: =APRIL!AG1 -> HIMALAYA MEDICAL AGENCIES | AI1: =APRIL!AI1 -> Maruthi | AK1: =APRIL!AK1 -> LAXMI SAI MEDICAL AGENCIES | AM1: =APRIL!AM1 -> Patwari Pharma | AO1: =APRIL!AO1 -> Vishnu & Co | AQ1: =APRIL!AQ1 -> SUMAN AGENCIES HYD PVT LTD | AS1: =APRIL!AS1 -> Sri Nirmala | AU1: =APRIL!AU1 -> SHREE SHARADA PHARMA | AW1: =APRIL!AW1 -> ALLIED PHARMA | AY1: =APRIL!AY1 -> GOEL DISTRIBUTER | BA1: =APRIL!BA1 -> KAMALESH PHARMA | BC1: =APRIL!BC1 -> ARVIND PHARMA DISTRIBUTER | BE1: =APRIL!BE1 -> GOEL PHARMA | BG1: =APRIL!BG1 -> KRISHNA PHARMACEUTICALS | BI1: =APRIL!BI1 -> AP DRUGS | BK1: =APRIL!BK1 -> MAWA PHARMACEUTICALS | BM1: =APRIL!BM1 -> TIRUMALA AGENCIES | BO1: =APRIL!BO1 -> SREE HARI MEDICALS | BQ1: =APRIL!BQ1 -> SREE VENKATESHWARA MEDISOLUTIONS | BS1: =APRIL!BS1 -> SRI BALAJI DRUGS | BU1: =APRIL!BU1 -> VISHNU MEDICAL HALL | BW1: =APRIL!BW1 -> HYDERABAD SPECIALITY DRUGS | BY1: =APRIL!BY1 -> LORVEN PHARMA & SURGICALS (CORP) | CA1: =APRIL!CA1 -> AK PHARMA | CC1: =APRIL!CC1 -> OPTIVAL HEALTHSOLUTIONS | CE1: =APRIL!CE1 -> BALAJI MEDICAL AGENCIES | CG1: =APRIL!CG1 -> S42 | CI1: =APRIL!CI1 -> S43 | CK1: =APRIL!CK1 -> S44 | CM1: =APRIL!CM1 -> S45 | CO1: =APRIL!CO1 -> S46 | CQ1: =APRIL!CQ1 -> S47 | CS1: =APRIL!CS1 -> S48 | CU1: =APRIL!CU1 -> S49 | CW1: =APRIL!CW1 -> S50 | CY1: BE TOTAL
B2: PTS | C2: Sale (Units) | D2: Closing Stock (Units) | E2: Sale (Units) | F2: Closing Stock (Units) | G2: Sale (Units) | H2: Closing Stock (Units) | I2: Sale (Units) | J2: Closing Stock (Units) | K2: Sale (Units) | L2: Closing Stock (Units) | M2: Sale (Units) | N2: Closing Stock (Units) | O2: Sale (Units) | P2: Closing Stock (Units) | Q2: Sale (Units) | R2: Closing Stock (Units) | S2: Sale (Units) | T2: Closing Stock (Units) | U2: Sale (Units) | V2: Closing Stock (Units) | W2: Sale (Units) | X2: Closing Stock (Units) | Y2: Sale (Units) | Z2: Closing Stock (Units) | AA2: Sale (Units) | AB2: Closing Stock (Units) | AC2: Sale (Units) | AD2: Closing Stock (Units) | AE2: Sale (Units) | AF2: Closing Stock (Units) | AG2: Sale (Units) | AH2: Closing Stock (Units) | AI2: Sale (Units) | AJ2: Closing Stock (Units) | AK2: Sale (Units) | AL2: Closing Stock (Units) | AM2: Sale (Units) | AN2: Closing Stock (Units) | AO2: Sale (Units) | AP2: Closing Stock (Units) | AQ2: Sale (Units) | AR2: Closing Stock (Units) | AS2: Sale (Units) | AT2: Closing Stock (Units) | AU2: Sale (Units) | AV2: Closing Stock (Units) | AW2: Sale (Units) | AX2: Closing Stock (Units) | AY2: Sale (Units) | AZ2: Closing Stock (Units) | BA2: Sale (Units) | BB2: Closing Stock (Units) | BC2: Sale (Units) | BD2: Closing Stock (Units) | BE2: Sale (Units) | BF2: Closing Stock (Units) | BG2: Sale (Units) | BH2: Closing Stock (Units) | BI2: Sale (Units) | BJ2: Closing Stock (Units) | BK2: Sale (Units) | BL2: Closing Stock (Units) | BM2: Sale (Units) | BN2: Closing Stock (Units) | BO2: Sale (Units) | BP2: Closing Stock (Units) | BQ2: Sale (Units) | BR2: Closing Stock (Units) | BS2: Sale (Units) | BT2: Closing Stock (Units) | BU2: Sale (Units) | BV2: Closing Stock (Units) | BW2: Sale (Units) | BX2: Closing Stock (Units) | BY2: Sale (Units) | BZ2: Closing Stock (Units) | CA2: Sale (Units) | CB2: Closing Stock (Units) | CC2: Sale (Units) | CD2: Closing Stock (Units) | CE2: Sale (Units) | CF2: Closing Stock (Units) | CG2: Sale (Units) | CH2: Closing Stock (Units) | CI2: Sale (Units) | CJ2: Closing Stock (Units) | CK2: Sale (Units) | CL2: Closing Stock (Units) | CM2: Sale (Units) | CN2: Closing Stock (Units) | CO2: Sale (Units) | CP2: Closing Stock (Units) | CQ2: Sale (Units) | CR2: Closing Stock (Units) | CS2: Sale (Units) | CT2: Closing Stock (Units) | CU2: Sale (Units) | CV2: Closing Stock (Units) | CW2: Sale (Units) | CX2: Closing Stock (Units) | CY2: Sale (Units) | CZ2: Closing Stock (Units)
A3: ALZIL - SR 23 10 TAB | B3: =IFERROR(VLOOKUP(A3,PRICELIST!$A$3:$D$138,4,0),"-") -> 167.79 | CY3: =C3+E3+G3+I3+K3+M3+O3+Q3+S3+U3+W3+Y3+AA3+AC3+AE3+AG3+AI3+AK3+AM3+AO3+AQ3+AS3+AU3+AW3+AY3+BA3+BC3+BE3+BG3+BI3+BK3+BM3+BO3+BQ3+BS3+BU3+BW3+BY3+CA3+CC3+CE3+CG3+CI3+CK3+CM3+CO3+CQ3+CS3+CU3+CW3 -> 0 | CZ3: =D3+F3+H3+J3+L3+N3+P3+R3+T3+V3+X3+Z3+AB3+AD3+AF3+AH3+AJ3+AL3+AN3+AP3+AR3+AT3+AV3+AX3+AZ3+BB3+BD3+BF3+BH3+BJ3+BL3+BN3+BP3+BR3+BT3+BV3+BX3+BZ3+CB3+CD3+CF3+CH3+CJ3+CL3+CN3+CP3+CR3+CT3+CV3+CX3 -> 0
A4: ALZIL- SR 11.5 10 TAB | B4: =IFERROR(VLOOKUP(A4,PRICELIST!$A$3:$D$138,4,0),"-") -> 112.5 | CY4: =C4+E4+G4+I4+K4+M4+O4+Q4+S4+U4+W4+Y4+AA4+AC4+AE4+AG4+AI4+AK4+AM4+AO4+AQ4+AS4+AU4+AW4+AY4+BA4+BC4+BE4+BG4+BI4+BK4+BM4+BO4+BQ4+BS4+BU4+BW4+BY4+CA4+CC4+CE4+CG4+CI4+CK4+CM4+CO4+CQ4+CS4+CU4+CW4 -> 0 | CZ4: =D4+F4+H4+J4+L4+N4+P4+R4+T4+V4+X4+Z4+AB4+AD4+AF4+AH4+AJ4+AL4+AN4+AP4+AR4+AT4+AV4+AX4+AZ4+BB4+BD4+BF4+BH4+BJ4+BL4+BN4+BP4+BR4+BT4+BV4+BX4+BZ4+CB4+CD4+CF4+CH4+CJ4+CL4+CN4+CP4+CR4+CT4+CV4+CX4 -> 0
A5: ALZIL-10 10 TAB | B5: =IFERROR(VLOOKUP(A5,PRICELIST!$A$3:$D$138,4,0),"-") -> 127.87 | G5: 3 | H5: 17 | CY5: =C5+E5+G5+I5+K5+M5+O5+Q5+S5+U5+W5+Y5+AA5+AC5+AE5+AG5+AI5+AK5+AM5+AO5+AQ5+AS5+AU5+AW5+AY5+BA5+BC5+BE5+BG5+BI5+BK5+BM5+BO5+BQ5+BS5+BU5+BW5+BY5+CA5+CC5+CE5+CG5+CI5+CK5+CM5+CO5+CQ5+CS5+CU5+CW5 -> 3 | CZ5: =D5+F5+H5+J5+L5+N5+P5+R5+T5+V5+X5+Z5+AB5+AD5+AF5+AH5+AJ5+AL5+AN5+AP5+AR5+AT5+AV5+AX5+AZ5+BB5+BD5+BF5+BH5+BJ5+BL5+BN5+BP5+BR5+BT5+BV5+BX5+BZ5+CB5+CD5+CF5+CH5+CJ5+CL5+CN5+CP5+CR5+CT5+CV5+CX5 -> 17
A6: ALZIL-5 10 TAB | B6: =IFERROR(VLOOKUP(A6,PRICELIST!$A$3:$D$138,4,0),"-") -> 88.7 | G6: 6 | H6: 19 | CY6: =C6+E6+G6+I6+K6+M6+O6+Q6+S6+U6+W6+Y6+AA6+AC6+AE6+AG6+AI6+AK6+AM6+AO6+AQ6+AS6+AU6+AW6+AY6+BA6+BC6+BE6+BG6+BI6+BK6+BM6+BO6+BQ6+BS6+BU6+BW6+BY6+CA6+CC6+CE6+CG6+CI6+CK6+CM6+CO6+CQ6+CS6+CU6+CW6 -> 6 | CZ6: =D6+F6+H6+J6+L6+N6+P6+R6+T6+V6+X6+Z6+AB6+AD6+AF6+AH6+AJ6+AL6+AN6+AP6+AR6+AT6+AV6+AX6+AZ6+BB6+BD6+BF6+BH6+BJ6+BL6+BN6+BP6+BR6+BT6+BV6+BX6+BZ6+CB6+CD6+CF6+CH6+CJ6+CL6+CN6+CP6+CR6+CT6+CV6+CX6 -> 19
A7: ALZIL M FORTE 10 TAB | B7: =IFERROR(VLOOKUP(A7,PRICELIST!$A$3:$D$138,4,0),"-") -> 171.64 | G7: 3 | H7: 11 | CY7: =C7+E7+G7+I7+K7+M7+O7+Q7+S7+U7+W7+Y7+AA7+AC7+AE7+AG7+AI7+AK7+AM7+AO7+AQ7+AS7+AU7+AW7+AY7+BA7+BC7+BE7+BG7+BI7+BK7+BM7+BO7+BQ7+BS7+BU7+BW7+BY7+CA7+CC7+CE7+CG7+CI7+CK7+CM7+CO7+CQ7+CS7+CU7+CW7 -> 3 | CZ7: =D7+F7+H7+J7+L7+N7+P7+R7+T7+V7+X7+Z7+AB7+AD7+AF7+AH7+AJ7+AL7+AN7+AP7+AR7+AT7+AV7+AX7+AZ7+BB7+BD7+BF7+BH7+BJ7+BL7+BN7+BP7+BR7+BT7+BV7+BX7+BZ7+CB7+CD7+CF7+CH7+CJ7+CL7+CN7+CP7+CR7+CT7+CV7+CX7 -> 11
A8: ALZIL-M 10 10 TAB | B8: =IFERROR(VLOOKUP(A8,PRICELIST!$A$3:$D$138,4,0),"-") -> 216 | G8: 46 | H8: 24 | CY8: =C8+E8+G8+I8+K8+M8+O8+Q8+S8+U8+W8+Y8+AA8+AC8+AE8+AG8+AI8+AK8+AM8+AO8+AQ8+AS8+AU8+AW8+AY8+BA8+BC8+BE8+BG8+BI8+BK8+BM8+BO8+BQ8+BS8+BU8+BW8+BY8+CA8+CC8+CE8+CG8+CI8+CK8+CM8+CO8+CQ8+CS8+CU8+CW8 -> 46 | CZ8: =D8+F8+H8+J8+L8+N8+P8+R8+T8+V8+X8+Z8+AB8+AD8+AF8+AH8+AJ8+AL8+AN8+AP8+AR8+AT8+AV8+AX8+AZ8+BB8+BD8+BF8+BH8+BJ8+BL8+BN8+BP8+BR8+BT8+BV8+BX8+BZ8+CB8+CD8+CF8+CH8+CJ8+CL8+CN8+CP8+CR8+CT8+CV8+CX8 -> 24
A9: ALZIL-M 5 10 TAB | B9: =IFERROR(VLOOKUP(A9,PRICELIST!$A$3:$D$138,4,0),"-") -> 163.93 | CY9: =C9+E9+G9+I9+K9+M9+O9+Q9+S9+U9+W9+Y9+AA9+AC9+AE9+AG9+AI9+AK9+AM9+AO9+AQ9+AS9+AU9+AW9+AY9+BA9+BC9+BE9+BG9+BI9+BK9+BM9+BO9+BQ9+BS9+BU9+BW9+BY9+CA9+CC9+CE9+CG9+CI9+CK9+CM9+CO9+CQ9+CS9+CU9+CW9 -> 0 | CZ9: =D9+F9+H9+J9+L9+N9+P9+R9+T9+V9+X9+Z9+AB9+AD9+AF9+AH9+AJ9+AL9+AN9+AP9+AR9+AT9+AV9+AX9+AZ9+BB9+BD9+BF9+BH9+BJ9+BL9+BN9+BP9+BR9+BT9+BV9+BX9+BZ9+CB9+CD9+CF9+CH9+CJ9+CL9+CN9+CP9+CR9+CT9+CV9+CX9 -> 0
A10: ALZIL GROUP | C10: =SUMPRODUCT($B3:$B9,C3:C9) -> 0 | D10: =SUMPRODUCT($B3:$B9,D3:D9) -> 0 | E10: =SUMPRODUCT($B3:$B9,E3:E9) -> 0 | F10: =SUMPRODUCT($B3:$B9,F3:F9) -> 0 | G10: =SUMPRODUCT($B3:$B9,G3:G9) -> 11366.73 | H10: =SUMPRODUCT($B3:$B9,H3:H9) -> 10931.13 | I10: =SUMPRODUCT($B3:$B9,I3:I9) -> 0 | J10: =SUMPRODUCT($B3:$B9,J3:J9) -> 0 | ... CZ10: =SUMPRODUCT($B3:$B9,CZ3:CZ9) -> 10931.13
A11: BRIVAZEN 100 (15T) | B11: =IFERROR(VLOOKUP(A11,PRICELIST!$A$3:$D$138,4,0),"-") -> 432.21 | G11: 24 | H11: 0 | CY11: =C11+E11+G11+I11+K11+M11+O11+Q11+S11+U11+W11+Y11+AA11+AC11+AE11+AG11+AI11+AK11+AM11+AO11+AQ11+AS11+AU11+AW11+AY11+BA11+BC11+BE11+BG11+BI11+BK11+BM11+BO11+BQ11+BS11+BU11+BW11+BY11+CA11+CC11+CE11+CG11+CI11+CK11+CM11+CO11+CQ11+CS11+CU11+CW11 -> 24 | CZ11: =D11+F11+H11+J11+L11+N11+P11+R11+T11+V11+X11+Z11+AB11+AD11+AF11+AH11+AJ11+AL11+AN11+AP11+AR11+AT11+AV11+AX11+AZ11+BB11+BD11+BF11+BH11+BJ11+BL11+BN11+BP11+BR11+BT11+BV11+BX11+BZ11+CB11+CD11+CF11+CH11+CJ11+CL11+CN11+CP11+CR11+CT11+CV11+CX11 -> 0
A12: BRIVAZEN 25 (15T) | B12: =IFERROR(VLOOKUP(A12,PRICELIST!$A$3:$D$138,4,0),"-") -> 107.11 | G12: 10 | H12: 20 | CY12: =C12+E12+G12+I12+K12+M12+O12+Q12+S12+U12+W12+Y12+AA12+AC12+AE12+AG12+AI12+AK12+AM12+AO12+AQ12+AS12+AU12+AW12+AY12+BA12+BC12+BE12+BG12+BI12+BK12+BM12+BO12+BQ12+BS12+BU12+BW12+BY12+CA12+CC12+CE12+CG12+CI12+CK12+CM12+CO12+CQ12+CS12+CU12+CW12 -> 10 | CZ12: =D12+F12+H12+J12+L12+N12+P12+R12+T12+V12+X12+Z12+AB12+AD12+AF12+AH12+AJ12+AL12+AN12+AP12+AR12+AT12+AV12+AX12+AZ12+BB12+BD12+BF12+BH12+BJ12+BL12+BN12+BP12+BR12+BT12+BV12+BX12+BZ12+CB12+CD12+CF12+CH12+CJ12+CL12+CN12+CP12+CR12+CT12+CV12+CX12 -> 20
A13: BRIVAZEN 50 (15T) | B13: =IFERROR(VLOOKUP(A13,PRICELIST!$A$3:$D$138,4,0),"-") -> 205.07 | G13: 80 | H13: 35 | CY13: =C13+E13+G13+I13+K13+M13+O13+Q13+S13+U13+W13+Y13+AA13+AC13+AE13+AG13+AI13+AK13+AM13+AO13+AQ13+AS13+AU13+AW13+AY13+BA13+BC13+BE13+BG13+BI13+BK13+BM13+BO13+BQ13+BS13+BU13+BW13+BY13+CA13+CC13+CE13+CG13+CI13+CK13+CM13+CO13+CQ13+CS13+CU13+CW13 -> 80 | CZ13: =D13+F13+H13+J13+L13+N13+P13+R13+T13+V13+X13+Z13+AB13+AD13+AF13+AH13+AJ13+AL13+AN13+AP13+AR13+AT13+AV13+AX13+AZ13+BB13+BD13+BF13+BH13+BJ13+BL13+BN13+BP13+BR13+BT13+BV13+BX13+BZ13+CB13+CD13+CF13+CH13+CJ13+CL13+CN13+CP13+CR13+CT13+CV13+CX13 -> 35
A14: BRIVAZEN 75 (15T) | B14: =IFERROR(VLOOKUP(A14,PRICELIST!$A$3:$D$138,4,0),"-") -> 322.71 | G14: 16 | H14: 4 | CY14: =C14+E14+G14+I14+K14+M14+O14+Q14+S14+U14+W14+Y14+AA14+AC14+AE14+AG14+AI14+AK14+AM14+AO14+AQ14+AS14+AU14+AW14+AY14+BA14+BC14+BE14+BG14+BI14+BK14+BM14+BO14+BQ14+BS14+BU14+BW14+BY14+CA14+CC14+CE14+CG14+CI14+CK14+CM14+CO14+CQ14+CS14+CU14+CW14 -> 16 | CZ14: =D14+F14+H14+J14+L14+N14+P14+R14+T14+V14+X14+Z14+AB14+AD14+AF14+AH14+AJ14+AL14+AN14+AP14+AR14+AT14+AV14+AX14+AZ14+BB14+BD14+BF14+BH14+BJ14+BL14+BN14+BP14+BR14+BT14+BV14+BX14+BZ14+CB14+CD14+CF14+CH14+CJ14+CL14+CN14+CP14+CR14+CT14+CV14+CX14 -> 4
A15: BRIVAZEN SR 100 (SALE) (10T) | B15: =IFERROR(VLOOKUP(A15,PRICELIST!$A$3:$D$138,4,0),"-") -> 272.23 | G15: 20 | H15: 16 | CY15: =C15+E15+G15+I15+K15+M15+O15+Q15+S15+U15+W15+Y15+AA15+AC15+AE15+AG15+AI15+AK15+AM15+AO15+AQ15+AS15+AU15+AW15+AY15+BA15+BC15+BE15+BG15+BI15+BK15+BM15+BO15+BQ15+BS15+BU15+BW15+BY15+CA15+CC15+CE15+CG15+CI15+CK15+CM15+CO15+CQ15+CS15+CU15+CW15 -> 20 | CZ15: =D15+F15+H15+J15+L15+N15+P15+R15+T15+V15+X15+Z15+AB15+AD15+AF15+AH15+AJ15+AL15+AN15+AP15+AR15+AT15+AV15+AX15+AZ15+BB15+BD15+BF15+BH15+BJ15+BL15+BN15+BP15+BR15+BT15+BV15+BX15+BZ15+CB15+CD15+CF15+CH15+CJ15+CL15+CN15+CP15+CR15+CT15+CV15+CX15 -> 16
A16: BRIVAZEN SR 200 (SALE) (10T) | B16: =IFERROR(VLOOKUP(A16,PRICELIST!$A$3:$D$138,4,0),"-") -> 352.76 | CY16: =C16+E16+G16+I16+K16+M16+O16+Q16+S16+U16+W16+Y16+AA16+AC16+AE16+AG16+AI16+AK16+AM16+AO16+AQ16+AS16+AU16+AW16+AY16+BA16+BC16+BE16+BG16+BI16+BK16+BM16+BO16+BQ16+BS16+BU16+BW16+BY16+CA16+CC16+CE16+CG16+CI16+CK16+CM16+CO16+CQ16+CS16+CU16+CW16 -> 0 | CZ16: =D16+F16+H16+J16+L16+N16+P16+R16+T16+V16+X16+Z16+AB16+AD16+AF16+AH16+AJ16+AL16+AN16+AP16+AR16+AT16+AV16+AX16+AZ16+BB16+BD16+BF16+BH16+BJ16+BL16+BN16+BP16+BR16+BT16+BV16+BX16+BZ16+CB16+CD16+CF16+CH16+CJ16+CL16+CN16+CP16+CR16+CT16+CV16+CX16 -> 0
A17: BRIVAZEN SR 50 (SALE) (10T) | B17: =IFERROR(VLOOKUP(A17,PRICELIST!$A$3:$D$138,4,0),"-") -> 137.57 | G17: 27 | H17: 30 | CY17: =C17+E17+G17+I17+K17+M17+O17+Q17+S17+U17+W17+Y17+AA17+AC17+AE17+AG17+AI17+AK17+AM17+AO17+AQ17+AS17+AU17+AW17+AY17+BA17+BC17+BE17+BG17+BI17+BK17+BM17+BO17+BQ17+BS17+BU17+BW17+BY17+CA17+CC17+CE17+CG17+CI17+CK17+CM17+CO17+CQ17+CS17+CU17+CW17 -> 27 | CZ17: =D17+F17+H17+J17+L17+N17+P17+R17+T17+V17+X17+Z17+AB17+AD17+AF17+AH17+AJ17+AL17+AN17+AP17+AR17+AT17+AV17+AX17+AZ17+BB17+BD17+BF17+BH17+BJ17+BL17+BN17+BP17+BR17+BT17+BV17+BX17+BZ17+CB17+CD17+CF17+CH17+CJ17+CL17+CN17+CP17+CR17+CT17+CV17+CX17 -> 30
A18: BRIVAZEN SOLUTION 200 ML | B18: =IFERROR(VLOOKUP(A18,PRICELIST!$A$3:$D$138,4,0),"-") -> 647.36 | G18: 1 | H18: 1 | CY18: =C18+E18+G18+I18+K18+M18+O18+Q18+S18+U18+W18+Y18+AA18+AC18+AE18+AG18+AI18+AK18+AM18+AO18+AQ18+AS18+AU18+AW18+AY18+BA18+BC18+BE18+BG18+BI18+BK18+BM18+BO18+BQ18+BS18+BU18+BW18+BY18+CA18+CC18+CE18+CG18+CI18+CK18+CM18+CO18+CQ18+CS18+CU18+CW18 -> 1 | CZ18: =D18+F18+H18+J18+L18+N18+P18+R18+T18+V18+X18+Z18+AB18+AD18+AF18+AH18+AJ18+AL18+AN18+AP18+AR18+AT18+AV18+AX18+AZ18+BB18+BD18+BF18+BH18+BJ18+BL18+BN18+BP18+BR18+BT18+BV18+BX18+BZ18+CB18+CD18+CF18+CH18+CJ18+CL18+CN18+CP18+CR18+CT18+CV18+CX18 -> 1
A19: BRIVAZEN INJECTION (5 ML) | B19: =IFERROR(VLOOKUP(A19,PRICELIST!$A$3:$D$138,4,0),"-") -> 110.25 | H19: 11 | CY19: =C19+E19+G19+I19+K19+M19+O19+Q19+S19+U19+W19+Y19+AA19+AC19+AE19+AG19+AI19+AK19+AM19+AO19+AQ19+AS19+AU19+AW19+AY19+BA19+BC19+BE19+BG19+BI19+BK19+BM19+BO19+BQ19+BS19+BU19+BW19+BY19+CA19+CC19+CE19+CG19+CI19+CK19+CM19+CO19+CQ19+CS19+CU19+CW19 -> 0 | CZ19: =D19+F19+H19+J19+L19+N19+P19+R19+T19+V19+X19+Z19+AB19+AD19+AF19+AH19+AJ19+AL19+AN19+AP19+AR19+AT19+AV19+AX19+AZ19+BB19+BD19+BF19+BH19+BJ19+BL19+BN19+BP19+BR19+BT19+BV19+BX19+BZ19+CB19+CD19+CF19+CH19+CJ19+CL19+CN19+CP19+CR19+CT19+CV19+CX19 -> 11
A20: BRIVAZEN GROUP | C20: =SUMPRODUCT($B11:$B19,C11:C19) -> 0 | D20: =SUMPRODUCT($B11:$B19,D11:D19) -> 0 | E20: =SUMPRODUCT($B11:$B19,E11:E19) -> 0 | F20: =SUMPRODUCT($B11:$B19,F11:F19) -> 0 | G20: =SUMPRODUCT($B11:$B19,G11:G19) -> 42819.45 | H20: =SUMPRODUCT($B11:$B19,H11:H19) -> 20953.38 | I20: =SUMPRODUCT($B11:$B19,I11:I19) -> 0 | J20: =SUMPRODUCT($B11:$B19,J11:J19) -> 0 | ... CZ20: =SUMPRODUCT($B11:$B19,CZ11:CZ19) -> 20953.38
A21: CELETOIN -100, 100 TABS (D) | B21: =IFERROR(VLOOKUP(A21,PRICELIST!$A$3:$D$138,4,0),"-") -> 128.88 | G21: 7 | H21: 21 | CY21: =C21+E21+G21+I21+K21+M21+O21+Q21+S21+U21+W21+Y21+AA21+AC21+AE21+AG21+AI21+AK21+AM21+AO21+AQ21+AS21+AU21+AW21+AY21+BA21+BC21+BE21+BG21+BI21+BK21+BM21+BO21+BQ21+BS21+BU21+BW21+BY21+CA21+CC21+CE21+CG21+CI21+CK21+CM21+CO21+CQ21+CS21+CU21+CW21 -> 7 | CZ21: =D21+F21+H21+J21+L21+N21+P21+R21+T21+V21+X21+Z21+AB21+AD21+AF21+AH21+AJ21+AL21+AN21+AP21+AR21+AT21+AV21+AX21+AZ21+BB21+BD21+BF21+BH21+BJ21+BL21+BN21+BP21+BR21+BT21+BV21+BX21+BZ21+CB21+CD21+CF21+CH21+CJ21+CL21+CN21+CP21+CR21+CT21+CV21+CX21 -> 21
A22: CELETOIN 300 30 TAB | B22: =IFERROR(VLOOKUP(A22,PRICELIST!$A$3:$D$138,4,0),"-") -> 120.53 | CY22: =C22+E22+G22+I22+K22+M22+O22+Q22+S22+U22+W22+Y22+AA22+AC22+AE22+AG22+AI22+AK22+AM22+AO22+AQ22+AS22+AU22+AW22+AY22+BA22+BC22+BE22+BG22+BI22+BK22+BM22+BO22+BQ22+BS22+BU22+BW22+BY22+CA22+CC22+CE22+CG22+CI22+CK22+CM22+CO22+CQ22+CS22+CU22+CW22 -> 0 | CZ22: =D22+F22+H22+J22+L22+N22+P22+R22+T22+V22+X22+Z22+AB22+AD22+AF22+AH22+AJ22+AL22+AN22+AP22+AR22+AT22+AV22+AX22+AZ22+BB22+BD22+BF22+BH22+BJ22+BL22+BN22+BP22+BR22+BT22+BV22+BX22+BZ22+CB22+CD22+CF22+CH22+CJ22+CL22+CN22+CP22+CR22+CT22+CV22+CX22 -> 0
A23: CELETOIN ER 300 30 TAB | B23: =IFERROR(VLOOKUP(A23,PRICELIST!$A$3:$D$138,4,0),"-") -> 144.29 | CY23: =C23+E23+G23+I23+K23+M23+O23+Q23+S23+U23+W23+Y23+AA23+AC23+AE23+AG23+AI23+AK23+AM23+AO23+AQ23+AS23+AU23+AW23+AY23+BA23+BC23+BE23+BG23+BI23+BK23+BM23+BO23+BQ23+BS23+BU23+BW23+BY23+CA23+CC23+CE23+CG23+CI23+CK23+CM23+CO23+CQ23+CS23+CU23+CW23 -> 0 | CZ23: =D23+F23+H23+J23+L23+N23+P23+R23+T23+V23+X23+Z23+AB23+AD23+AF23+AH23+AJ23+AL23+AN23+AP23+AR23+AT23+AV23+AX23+AZ23+BB23+BD23+BF23+BH23+BJ23+BL23+BN23+BP23+BR23+BT23+BV23+BX23+BZ23+CB23+CD23+CF23+CH23+CJ23+CL23+CN23+CP23+CR23+CT23+CV23+CX23 -> 0
A24: CELETOIN GROUP | C24: =SUMPRODUCT($B21:$B23,C21:C23) -> 0 | D24: =SUMPRODUCT($B21:$B23,D21:D23) -> 0 | E24: =SUMPRODUCT($B21:$B23,E21:E23) -> 0 | F24: =SUMPRODUCT($B21:$B23,F21:F23) -> 0 | G24: =SUMPRODUCT($B21:$B23,G21:G23) -> 902.16 | H24: =SUMPRODUCT($B21:$B23,H21:H23) -> 2706.48 | I24: =SUMPRODUCT($B21:$B23,I21:I23) -> 0 | J24: =SUMPRODUCT($B21:$B23,J21:J23) -> 0 | ... CZ24: =SUMPRODUCT($B21:$B23,CZ21:CZ23) -> 2706.48
A25: LURASID 40 (10T) | B25: =IFERROR(VLOOKUP(A25,PRICELIST!$A$3:$D$138,4,0),"-") -> 110.57 | CY25: =C25+E25+G25+I25+K25+M25+O25+Q25+S25+U25+W25+Y25+AA25+AC25+AE25+AG25+AI25+AK25+AM25+AO25+AQ25+AS25+AU25+AW25+AY25+BA25+BC25+BE25+BG25+BI25+BK25+BM25+BO25+BQ25+BS25+BU25+BW25+BY25+CA25+CC25+CE25+CG25+CI25+CK25+CM25+CO25+CQ25+CS25+CU25+CW25 -> 0 | CZ25: =D25+F25+H25+J25+L25+N25+P25+R25+T25+V25+X25+Z25+AB25+AD25+AF25+AH25+AJ25+AL25+AN25+AP25+AR25+AT25+AV25+AX25+AZ25+BB25+BD25+BF25+BH25+BJ25+BL25+BN25+BP25+BR25+BT25+BV25+BX25+BZ25+CB25+CD25+CF25+CH25+CJ25+CL25+CN25+CP25+CR25+CT25+CV25+CX25 -> 0
A26: LURASID 80 (10T) | B26: =IFERROR(VLOOKUP(A26,PRICELIST!$A$3:$D$138,4,0),"-") -> 184.82 | CY26: =C26+E26+G26+I26+K26+M26+O26+Q26+S26+U26+W26+Y26+AA26+AC26+AE26+AG26+AI26+AK26+AM26+AO26+AQ26+AS26+AU26+AW26+AY26+BA26+BC26+BE26+BG26+BI26+BK26+BM26+BO26+BQ26+BS26+BU26+BW26+BY26+CA26+CC26+CE26+CG26+CI26+CK26+CM26+CO26+CQ26+CS26+CU26+CW26 -> 0 | CZ26: =D26+F26+H26+J26+L26+N26+P26+R26+T26+V26+X26+Z26+AB26+AD26+AF26+AH26+AJ26+AL26+AN26+AP26+AR26+AT26+AV26+AX26+AZ26+BB26+BD26+BF26+BH26+BJ26+BL26+BN26+BP26+BR26+BT26+BV26+BX26+BZ26+CB26+CD26+CF26+CH26+CJ26+CL26+CN26+CP26+CR26+CT26+CV26+CX26 -> 0
A27: LURASID GROUP | C27: =SUMPRODUCT($B25:$B26,C25:C26) -> 0 | D27: =SUMPRODUCT($B25:$B26,D25:D26) -> 0 | E27: =SUMPRODUCT($B25:$B26,E25:E26) -> 0 | F27: =SUMPRODUCT($B25:$B26,F25:F26) -> 0 | G27: =SUMPRODUCT($B25:$B26,G25:G26) -> 0 | H27: =SUMPRODUCT($B25:$B26,H25:H26) -> 0 | I27: =SUMPRODUCT($B25:$B26,I25:I26) -> 0 | J27: =SUMPRODUCT($B25:$B26,J25:J26) -> 0 | ... CZ27: =SUMPRODUCT($B25:$B26,CZ25:CZ26) -> 0
A28: MIRNITE MELTAB-15 10 TAB | B28: =IFERROR(VLOOKUP(A28,PRICELIST!$A$3:$D$138,4,0),"-") -> 113.79 | CY28: =C28+E28+G28+I28+K28+M28+O28+Q28+S28+U28+W28+Y28+AA28+AC28+AE28+AG28+AI28+AK28+AM28+AO28+AQ28+AS28+AU28+AW28+AY28+BA28+BC28+BE28+BG28+BI28+BK28+BM28+BO28+BQ28+BS28+BU28+BW28+BY28+CA28+CC28+CE28+CG28+CI28+CK28+CM28+CO28+CQ28+CS28+CU28+CW28 -> 0 | CZ28: =D28+F28+H28+J28+L28+N28+P28+R28+T28+V28+X28+Z28+AB28+AD28+AF28+AH28+AJ28+AL28+AN28+AP28+AR28+AT28+AV28+AX28+AZ28+BB28+BD28+BF28+BH28+BJ28+BL28+BN28+BP28+BR28+BT28+BV28+BX28+BZ28+CB28+CD28+CF28+CH28+CJ28+CL28+CN28+CP28+CR28+CT28+CV28+CX28 -> 0
A29: MIRNITE MELTAB-30 10 TAB | B29: =IFERROR(VLOOKUP(A29,PRICELIST!$A$3:$D$138,4,0),"-") -> 188.04 | CY29: =C29+E29+G29+I29+K29+M29+O29+Q29+S29+U29+W29+Y29+AA29+AC29+AE29+AG29+AI29+AK29+AM29+AO29+AQ29+AS29+AU29+AW29+AY29+BA29+BC29+BE29+BG29+BI29+BK29+BM29+BO29+BQ29+BS29+BU29+BW29+BY29+CA29+CC29+CE29+CG29+CI29+CK29+CM29+CO29+CQ29+CS29+CU29+CW29 -> 0 | CZ29: =D29+F29+H29+J29+L29+N29+P29+R29+T29+V29+X29+Z29+AB29+AD29+AF29+AH29+AJ29+AL29+AN29+AP29+AR29+AT29+AV29+AX29+AZ29+BB29+BD29+BF29+BH29+BJ29+BL29+BN29+BP29+BR29+BT29+BV29+BX29+BZ29+CB29+CD29+CF29+CH29+CJ29+CL29+CN29+CP29+CR29+CT29+CV29+CX29 -> 0
A30: MIRNITE MELTAB-7.5 10 TAB | B30: =IFERROR(VLOOKUP(A30,PRICELIST!$A$3:$D$138,4,0),"-") -> 68.16 | CY30: =C30+E30+G30+I30+K30+M30+O30+Q30+S30+U30+W30+Y30+AA30+AC30+AE30+AG30+AI30+AK30+AM30+AO30+AQ30+AS30+AU30+AW30+AY30+BA30+BC30+BE30+BG30+BI30+BK30+BM30+BO30+BQ30+BS30+BU30+BW30+BY30+CA30+CC30+CE30+CG30+CI30+CK30+CM30+CO30+CQ30+CS30+CU30+CW30 -> 0 | CZ30: =D30+F30+H30+J30+L30+N30+P30+R30+T30+V30+X30+Z30+AB30+AD30+AF30+AH30+AJ30+AL30+AN30+AP30+AR30+AT30+AV30+AX30+AZ30+BB30+BD30+BF30+BH30+BJ30+BL30+BN30+BP30+BR30+BT30+BV30+BX30+BZ30+CB30+CD30+CF30+CH30+CJ30+CL30+CN30+CP30+CR30+CT30+CV30+CX30 -> 0
A31: MIRNITE-15 10 TAB | B31: =IFERROR(VLOOKUP(A31,PRICELIST!$A$3:$D$138,4,0),"-") -> 101.57 | CY31: =C31+E31+G31+I31+K31+M31+O31+Q31+S31+U31+W31+Y31+AA31+AC31+AE31+AG31+AI31+AK31+AM31+AO31+AQ31+AS31+AU31+AW31+AY31+BA31+BC31+BE31+BG31+BI31+BK31+BM31+BO31+BQ31+BS31+BU31+BW31+BY31+CA31+CC31+CE31+CG31+CI31+CK31+CM31+CO31+CQ31+CS31+CU31+CW31 -> 0 | CZ31: =D31+F31+H31+J31+L31+N31+P31+R31+T31+V31+X31+Z31+AB31+AD31+AF31+AH31+AJ31+AL31+AN31+AP31+AR31+AT31+AV31+AX31+AZ31+BB31+BD31+BF31+BH31+BJ31+BL31+BN31+BP31+BR31+BT31+BV31+BX31+BZ31+CB31+CD31+CF31+CH31+CJ31+CL31+CN31+CP31+CR31+CT31+CV31+CX31 -> 0
A32: MIRNITE-30 10 TAB | B32: =IFERROR(VLOOKUP(A32,PRICELIST!$A$3:$D$138,4,0),"-") -> 164.73 | CY32: =C32+E32+G32+I32+K32+M32+O32+Q32+S32+U32+W32+Y32+AA32+AC32+AE32+AG32+AI32+AK32+AM32+AO32+AQ32+AS32+AU32+AW32+AY32+BA32+BC32+BE32+BG32+BI32+BK32+BM32+BO32+BQ32+BS32+BU32+BW32+BY32+CA32+CC32+CE32+CG32+CI32+CK32+CM32+CO32+CQ32+CS32+CU32+CW32 -> 0 | CZ32: =D32+F32+H32+J32+L32+N32+P32+R32+T32+V32+X32+Z32+AB32+AD32+AF32+AH32+AJ32+AL32+AN32+AP32+AR32+AT32+AV32+AX32+AZ32+BB32+BD32+BF32+BH32+BJ32+BL32+BN32+BP32+BR32+BT32+BV32+BX32+BZ32+CB32+CD32+CF32+CH32+CJ32+CL32+CN32+CP32+CR32+CT32+CV32+CX32 -> 0
A33: MIRNITE-7.5 10 TAB | B33: =IFERROR(VLOOKUP(A33,PRICELIST!$A$3:$D$138,4,0),"-") -> 78.1 | CY33: =C33+E33+G33+I33+K33+M33+O33+Q33+S33+U33+W33+Y33+AA33+AC33+AE33+AG33+AI33+AK33+AM33+AO33+AQ33+AS33+AU33+AW33+AY33+BA33+BC33+BE33+BG33+BI33+BK33+BM33+BO33+BQ33+BS33+BU33+BW33+BY33+CA33+CC33+CE33+CG33+CI33+CK33+CM33+CO33+CQ33+CS33+CU33+CW33 -> 0 | CZ33: =D33+F33+H33+J33+L33+N33+P33+R33+T33+V33+X33+Z33+AB33+AD33+AF33+AH33+AJ33+AL33+AN33+AP33+AR33+AT33+AV33+AX33+AZ33+BB33+BD33+BF33+BH33+BJ33+BL33+BN33+BP33+BR33+BT33+BV33+BX33+BZ33+CB33+CD33+CF33+CH33+CJ33+CL33+CN33+CP33+CR33+CT33+CV33+CX33 -> 0
A34: MIRNITE GROUP | C34: =SUMPRODUCT($B28:$B33,C28:C33) -> 0 | D34: =SUMPRODUCT($B28:$B33,D28:D33) -> 0 | E34: =SUMPRODUCT($B28:$B33,E28:E33) -> 0 | F34: =SUMPRODUCT($B28:$B33,F28:F33) -> 0 | G34: =SUMPRODUCT($B28:$B33,G28:G33) -> 0 | H34: =SUMPRODUCT($B28:$B33,H28:H33) -> 0 | I34: =SUMPRODUCT($B28:$B33,I28:I33) -> 0 | J34: =SUMPRODUCT($B28:$B33,J28:J33) -> 0 | ... CZ34: =SUMPRODUCT($B28:$B33,CZ28:CZ33) -> 0
A35: NAPRA-D 250 10 TAB | B35: =IFERROR(VLOOKUP(A35,PRICELIST!$A$3:$D$138,4,0),"-") -> 60.11 | CY35: =C35+E35+G35+I35+K35+M35+O35+Q35+S35+U35+W35+Y35+AA35+AC35+AE35+AG35+AI35+AK35+AM35+AO35+AQ35+AS35+AU35+AW35+AY35+BA35+BC35+BE35+BG35+BI35+BK35+BM35+BO35+BQ35+BS35+BU35+BW35+BY35+CA35+CC35+CE35+CG35+CI35+CK35+CM35+CO35+CQ35+CS35+CU35+CW35 -> 0 | CZ35: =D35+F35+H35+J35+L35+N35+P35+R35+T35+V35+X35+Z35+AB35+AD35+AF35+AH35+AJ35+AL35+AN35+AP35+AR35+AT35+AV35+AX35+AZ35+BB35+BD35+BF35+BH35+BJ35+BL35+BN35+BP35+BR35+BT35+BV35+BX35+BZ35+CB35+CD35+CF35+CH35+CJ35+CL35+CN35+CP35+CR35+CT35+CV35+CX35 -> 0
A36: NAPRA-D 500 10 TAB | B36: =IFERROR(VLOOKUP(A36,PRICELIST!$A$3:$D$138,4,0),"-") -> 91.2 | CY36: =C36+E36+G36+I36+K36+M36+O36+Q36+S36+U36+W36+Y36+AA36+AC36+AE36+AG36+AI36+AK36+AM36+AO36+AQ36+AS36+AU36+AW36+AY36+BA36+BC36+BE36+BG36+BI36+BK36+BM36+BO36+BQ36+BS36+BU36+BW36+BY36+CA36+CC36+CE36+CG36+CI36+CK36+CM36+CO36+CQ36+CS36+CU36+CW36 -> 0 | CZ36: =D36+F36+H36+J36+L36+N36+P36+R36+T36+V36+X36+Z36+AB36+AD36+AF36+AH36+AJ36+AL36+AN36+AP36+AR36+AT36+AV36+AX36+AZ36+BB36+BD36+BF36+BH36+BJ36+BL36+BN36+BP36+BR36+BT36+BV36+BX36+BZ36+CB36+CD36+CF36+CH36+CJ36+CL36+CN36+CP36+CR36+CT36+CV36+CX36 -> 0
A37: NAPRA D GROUP | C37: =SUMPRODUCT($B35:$B36,C35:C36) -> 0 | D37: =SUMPRODUCT($B35:$B36,D35:D36) -> 0 | E37: =SUMPRODUCT($B35:$B36,E35:E36) -> 0 | F37: =SUMPRODUCT($B35:$B36,F35:F36) -> 0 | G37: =SUMPRODUCT($B35:$B36,G35:G36) -> 0 | H37: =SUMPRODUCT($B35:$B36,H35:H36) -> 0 | I37: =SUMPRODUCT($B35:$B36,I35:I36) -> 0 | J37: =SUMPRODUCT($B35:$B36,J35:J36) -> 0 | ... CZ37: =SUMPRODUCT($B35:$B36,CZ35:CZ36) -> 0
A38: NEMDAA 10 10 TAB | B38: =IFERROR(VLOOKUP(A38,PRICELIST!$A$3:$D$138,4,0),"-") -> 159.75 | CY38: =C38+E38+G38+I38+K38+M38+O38+Q38+S38+U38+W38+Y38+AA38+AC38+AE38+AG38+AI38+AK38+AM38+AO38+AQ38+AS38+AU38+AW38+AY38+BA38+BC38+BE38+BG38+BI38+BK38+BM38+BO38+BQ38+BS38+BU38+BW38+BY38+CA38+CC38+CE38+CG38+CI38+CK38+CM38+CO38+CQ38+CS38+CU38+CW38 -> 0 | CZ38: =D38+F38+H38+J38+L38+N38+P38+R38+T38+V38+X38+Z38+AB38+AD38+AF38+AH38+AJ38+AL38+AN38+AP38+AR38+AT38+AV38+AX38+AZ38+BB38+BD38+BF38+BH38+BJ38+BL38+BN38+BP38+BR38+BT38+BV38+BX38+BZ38+CB38+CD38+CF38+CH38+CJ38+CL38+CN38+CP38+CR38+CT38+CV38+CX38 -> 0
A39: NEMDAA 5 10 TAB | B39: =IFERROR(VLOOKUP(A39,PRICELIST!$A$3:$D$138,4,0),"-") -> 83.59 | CY39: =C39+E39+G39+I39+K39+M39+O39+Q39+S39+U39+W39+Y39+AA39+AC39+AE39+AG39+AI39+AK39+AM39+AO39+AQ39+AS39+AU39+AW39+AY39+BA39+BC39+BE39+BG39+BI39+BK39+BM39+BO39+BQ39+BS39+BU39+BW39+BY39+CA39+CC39+CE39+CG39+CI39+CK39+CM39+CO39+CQ39+CS39+CU39+CW39 -> 0 | CZ39: =D39+F39+H39+J39+L39+N39+P39+R39+T39+V39+X39+Z39+AB39+AD39+AF39+AH39+AJ39+AL39+AN39+AP39+AR39+AT39+AV39+AX39+AZ39+BB39+BD39+BF39+BH39+BJ39+BL39+BN39+BP39+BR39+BT39+BV39+BX39+BZ39+CB39+CD39+CF39+CH39+CJ39+CL39+CN39+CP39+CR39+CT39+CV39+CX39 -> 0
A40: NEMDAA GROUP | C40: =SUMPRODUCT($B38:$B39,C38:C39) -> 0 | D40: =SUMPRODUCT($B38:$B39,D38:D39) -> 0 | E40: =SUMPRODUCT($B38:$B39,E38:E39) -> 0 | F40: =SUMPRODUCT($B38:$B39,F38:F39) -> 0 | G40: =SUMPRODUCT($B38:$B39,G38:G39) -> 0 | H40: =SUMPRODUCT($B38:$B39,H38:H39) -> 0 | I40: =SUMPRODUCT($B38:$B39,I38:I39) -> 0 | J40: =SUMPRODUCT($B38:$B39,J38:J39) -> 0 | ... CZ40: =SUMPRODUCT($B38:$B39,CZ38:CZ39) -> 0
...

Sheet JUN
A1: BRANDS | C1: =APRIL!C1 -> VASU PHARMA DRUGS PVT LTD | E1: =APRIL!E1 -> PRAKASH PHARMA DISTRIBUTORS | G1: =APRIL!G1 -> Divya Pharma | I1: =APRIL!I1 -> KEIMED PRIVATE LIMITED | K1: =APRIL!K1 -> SAI SRIDHAR PHARMA PVT LTD | M1: =APRIL!M1 -> SRI VENKATARAGHAVA AGENCIES | O1: =APRIL!O1 -> SHREEJI DIST PVT LTD | Q1: =APRIL!Q1 -> SVS PHARMA | S1: =APRIL!S1 -> PHARMA DISTRIBUTORS | U1: =APRIL!U1 -> SAI PHARMA DISTRIBUTERS PVT LTD | W1: =APRIL!W1 -> ALANKRITA AGENCIES | Y1: =APRIL!Y1 -> JAYA SURG & PHARMA PVT LTD | AA1: =APRIL!AA1 -> MANASA MEDICAL AGENCIES | AC1: =APRIL!AC1 -> KARTHICK AGENCIES | AE1: =APRIL!AE1 -> NIRMALA AGENCIES | AG1: =APRIL!AG1 -> HIMALAYA MEDICAL AGENCIES | AI1: =APRIL!AI1 -> Maruthi | AK1: =APRIL!AK1 -> LAXMI SAI MEDICAL AGENCIES | AM1: =APRIL!AM1 -> Patwari Pharma | AO1: =APRIL!AO1 -> Vishnu & Co | AQ1: =APRIL!AQ1 -> SUMAN AGENCIES HYD PVT LTD | AS1: =APRIL!AS1 -> Sri Nirmala | AU1: =APRIL!AU1 -> SHREE SHARADA PHARMA | AW1: =APRIL!AW1 -> ALLIED PHARMA | AY1: =APRIL!AY1 -> GOEL DISTRIBUTER | BA1: =APRIL!BA1 -> KAMALESH PHARMA | BC1: =APRIL!BC1 -> ARVIND PHARMA DISTRIBUTER | BE1: =APRIL!BE1 -> GOEL PHARMA | BG1: =APRIL!BG1 -> KRISHNA PHARMACEUTICALS | BI1: =APRIL!BI1 -> AP DRUGS | BK1: =APRIL!BK1 -> MAWA PHARMACEUTICALS | BM1: =APRIL!BM1 -> TIRUMALA AGENCIES | BO1: =APRIL!BO1 -> SREE HARI MEDICALS | BQ1: =APRIL!BQ1 -> SREE VENKATESHWARA MEDISOLUTIONS | BS1: =APRIL!BS1 -> SRI BALAJI DRUGS | BU1: =APRIL!BU1 -> VISHNU MEDICAL HALL | BW1: =APRIL!BW1 -> HYDERABAD SPECIALITY DRUGS | BY1: =APRIL!BY1 -> LORVEN PHARMA & SURGICALS (CORP) | CA1: =APRIL!CA1 -> AK PHARMA | CC1: =APRIL!CC1 -> OPTIVAL HEALTHSOLUTIONS | CE1: =APRIL!CE1 -> BALAJI MEDICAL AGENCIES | CG1: =APRIL!CG1 -> S42 | CI1: =APRIL!CI1 -> S43 | CK1: =APRIL!CK1 -> S44 | CM1: =APRIL!CM1 -> S45 | CO1: =APRIL!CO1 -> S46 | CQ1: =APRIL!CQ1 -> S47 | CS1: =APRIL!CS1 -> S48 | CU1: =APRIL!CU1 -> S49 | CW1: =APRIL!CW1 -> S50 | CY1: BE TOTAL
